Workbook

Sheet ERROR FINAL
E1: FORMATO | AP1: Código: F05-GA-PR-01 | AY1: Q3/Q1 | AZ1: 100 | BA1: 125 | BB1: 160 | BC1: 200 | BD1: 400 | BE1: 500
E2: INGRESO DE DATOS DE LA VERIFICACIÓN INICIAL DE MEDIDORES EN LA COMPUTADORA | AP2: Versión: 08 | AY2: Q3 (m3/h): | AZ2: 1.6 | BA2: 2.5 | BB2: 4 | BC2: 6.3
AP3: Fecha de Vigencia: 2024-05-14
A4: Q3 (m3/h): | E4: 2.5 | J4: Alcance Q3/Q1: | O4: 160 | S4: MAXIMO ERROR PERMISIBLE (EMP): | AF4: Q3 | AH4: Q2 | AK4: Q1 | AN4: Revisado por: | AP4: - | AR4: Fecha: | AT4: -
A5: Presión Estática: 0=conforme; 1 = Daño Físico; 2 = Fuga; 3 = Picado; 4 = Desfasado; 5 = Paralizado | AF5: (±) 2% | AH5: (±) 2% | AK5: (±) 5% | AN5: Aprobado por: | AP5: - | AR5: Fecha: | AT5: -
A6: Item | B6: Fecha de Ensayo presion estatica | C6: Fecha de Ensayo errores de indicacion | D6: N° de banco de ensayo | E6: 1' Técnico | F6: Nro de ceritificado | G6: # Medidor | H6: Presión Estática | J6: =+E4*1000 -> 2500 | V6: =AH6*1.6 -> 25 | AH6: =J6/O4 -> 15.625 | AT6: Estado
J7: Q3 | V7: Q2 | AH7: Q1 | AY7: RANGOS ACEPTABLES DE CAUDAL
H8: Presión (bar) | I8: Estado | J8: Temperatura | K8: Presión Entrada | L8: Presión Salida | M8: L.I. | N8: L.F. | O8: Vol. P | P8: Tiempo | T8: Q3 | U8: E % | V8: Temperatura | W8: Presión Entrada | X8: Presión Salida | Y8: L.I. | Z8: L.F. | AA8: Vol. P | AB8: Tiempo | AF8: Q2 | AG8: E % | AH8: Temperatura | AI8: Presión Entrada | AJ8: Presión Salida | AK8: L.I. | AL8: L.F. | AM8: Vol. P | AN8: Tiempo | AR8: Q1 | AS8: E % | AX8: Caudal | AY8: Q1 | AZ8: Q2 | BA8: Q3 | BB8: Ley Signos y Errores
A9: 1 | B9: 45920 | C9: =B9 -> 45920 | D9: 3 | E9: 8 | G9: PA25516865 | H9: 25.6 | I9: 0 | J9: 21 | K9: 8.49 | L9: 0.549 | M9: 244.48 | N9: 344.05 | O9: 100.69 | P9: 2,30,160 | Q9: =LEFT(P9,1) -> 2 | R9: =RIGHT(P9,6) -> 30,160 | S9: =+(Q9*60+R9)/(60*60) -> 0.041711111 | T9: =+O9/S9 -> 2413.9851 | U9: =+(((N9-M9-O9)/O9)*100) -> -1.112325 | V9: 20.5 | W9: 1.102 | X9: 1.094 | Y9: 371.08 | Z9: 381.03 | AA9: 10.01 | AB9: 22,55,230 | AC9: =LEFT(AB9,2) -> 22 | AD9: =RIGHT(AB9,6) -> 55,230 | AE9: =+(AC9*60+AD9)/(60*60) -> 0.38200833 | AF9: =+AA9/AE9 -> 26.203617 | AG9: =+(((Z9-Y9-AA9)/AA9)*100) -> -0.5994006 | AH9: 21 | AI9: 1.098 | AJ9: 1.088 | AK9: =Z9 -> 381.03 | AL9: 386.02 | AM9: 5.009 | AN9: 18,15,540 | AO9: =LEFT(AN9,2) -> 18 | AP9: =RIGHT(AN9,6) -> 15,540 | AQ9: =+(AO9*60+AP9)/(60*60) -> 0.30431667 | AR9: =+AM9/AQ9 -> 16.459828 | AS9: =+(((AL9-AK9-AM9)/AM9)*100) -> -0.37931723 | AT9: =IF(I9>=1,"NO CONFORME",IF(BK9="SIGDIFERENTES",BC9,BL9)) -> CONFORME | AU9: =B9<=C9 -> TRUE | AV9: =N9<Y9 -> TRUE | AW9: =Z9<=AK9 -> TRUE | AX9: =IF(I9>=1,"Qcorrecto",IF(AND(AY9="aceptable",AZ9="aceptable",BA9="aceptable"),"Qcorrecto","Qincorrecto")) -> Qcorrecto | AY9: =IF(AR9<$AH$6,"error",IF(AR9>$AH$6*1.1,"error","aceptable")) -> aceptable | AZ9: =IF(AF9<$V$6,"error",IF(AF9>$V$6*1.1,"error","aceptable")) -> aceptable | BA9: =IF(T9<$J$6*0.9,"error",IF(T9>$J$6,"error","aceptable")) -> aceptable | BB9: =(IF(ABS(U9)<1.05,"CONFORME",IF(ABS(AG9)<1.05,"CONFORME",IF(ABS(AS9)<2.55,"CONFORME","NO CONFORME")))) -> CONFORME | BC9: =(IF(ABS(U9)>2.05,"NO CONFORME",IF(ABS(AG9)>2.05,"NO CONFORME",IF(ABS(AS9)>5.05,"NO CONFORME","CONFORME")))) -> CONFORME | BD9: =SIGN(U9) -> -1 | BE9: =SIGN(AG9) -> -1 | BF9: =SIGN(AS9) -> -1 | BG9: =CONCATENATE(BD9,BE9,BF9) -> -1-1-1 | BH9: =IF(BG9="111","SI","SD") -> SD | BI9: =IF(BG9="-1-1-1","SI","SD") -> SI | BJ9: =OR(BH9="SI",BI9="SI") -> TRUE | BK9: =IF(BJ9=FALSE,"SIGDIFERENTES","SIGIGUALES") -> SIGIGUALES | BL9: =IF(BC9="NO CONFORME","NO CONFORME",IF(BB9="CONFORME","CONFORME","NO CONFORME")) -> CONFORME
A10: 2 | B10: =B9 -> 45920 | C10: =C9 -> 45920 | D10: =D9 -> 3 | E10: =E9 -> 8 | G10: PA25516866 | H10: =H9 -> 25.6 | I10: =I9 -> 0 | J10: =J9 -> 21 | K10: =K9 -> 8.49 | L10: =L9 -> 0.549 | M10: 205.75 | N10: 305.34 | O10: =O9 -> 100.69 | P10: =P9 -> 2,30,160 | Q10: =LEFT(P10,1) -> 2 | R10: =RIGHT(P10,6) -> 30,160 | S10: =+(Q10*60+R10)/(60*60) -> 0.041711111 | T10: =+O10/S10 -> 2413.9851 | U10: =+(((N10-M10-O10)/O10)*100) -> -1.092462 | V10: =V9 -> 20.5 | W10: =W9 -> 1.102 | X10: =X9 -> 1.094 | Y10: 332.45 | Z10: 342.46 | AA10: =AA9 -> 10.01 | AB10: =AB9 -> 22,55,230 | AC10: =LEFT(AB10,2) -> 22 | AD10: =RIGHT(AB10,6) -> 55,230 | AE10: =+(AC10*60+AD10)/(60*60) -> 0.38200833 | AF10: =+AA10/AE10 -> 26.203617 | AG10: =+(((Z10-Y10-AA10)/AA10)*100) -> -8.8729113e-14 | AH10: =AH9 -> 21 | AI10: =AI9 -> 1.098 | AJ10: =AJ9 -> 1.088 | AK10: =Z10 -> 342.46 | AL10: 347.51 | AM10: =AM9 -> 5.009 | AN10: =AN9 -> 18,15,540 | AO10: =LEFT(AN10,2) -> 18 | AP10: =RIGHT(AN10,6) -> 15,540 | AQ10: =+(AO10*60+AP10)/(60*60) -> 0.30431667 | AR10: =+AM10/AQ10 -> 16.459828 | AS10: =+(((AL10-AK10-AM10)/AM10)*100) -> 0.81852665 | AT10: =IF(I10>=1,"NO CONFORME",IF(BK10="SIGDIFERENTES",BC10,BL10)) -> CONFORME | AU10: =B10<=C10 -> TRUE | AV10: =N10<Y10 -> TRUE | AW10: =Z10<=AK10 -> TRUE | AX10: =IF(I10>=1,"Qcorrecto",IF(AND(AY10="aceptable",AZ10="aceptable",BA10="aceptable"),"Qcorrecto","Qincorrecto")) -> Qcorrecto | AY10: =IF(AR10<$AH$6,"error",IF(AR10>$AH$6*1.1,"error","aceptable")) -> aceptable | AZ10: =IF(AF10<$V$6,"error",IF(AF10>$V$6*1.1,"error","aceptable")) -> aceptable | BA10: =IF(T10<$J$6*0.9,"error",IF(T10>$J$6,"error","aceptable")) -> aceptable | BB10: =(IF(ABS(U10)<1.05,"CONFORME",IF(ABS(AG10)<1.05,"CONFORME",IF(ABS(AS10)<2.55,"CONFORME","NO CONFORME")))) -> CONFORME | BC10: =(IF(ABS(U10)>2.05,"NO CONFORME",IF(ABS(AG10)>2.05,"NO CONFORME",IF(ABS(AS10)>5.05,"NO CONFORME","CONFORME")))) -> CONFORME | BD10: =SIGN(U10) -> -1 | BE10: =SIGN(AG10) -> -1 | BF10: =SIGN(AS10) -> 1 | BG10: =CONCATENATE(BD10,BE10,BF10) -> -1-11 | BH10: =IF(BG10="111","SI","SD") -> SD | BI10: =IF(BG10="-1-1-1","SI","SD") -> SD | BJ10: =OR(BH10="SI",BI10="SI") -> FALSE | BK10: =IF(BJ10=FALSE,"SIGDIFERENTES","SIGIGUALES") -> SIGDIFERENTES | BL10: =IF(BC10="NO CONFORME","NO CONFORME",IF(BB10="CONFORME","CONFORME","NO CONFORME")) -> CONFORME
A11: 3 | B11: =B10 -> 45920 | C11: =C10 -> 45920 | D11: =D10 -> 3 | E11: =E10 -> 8 | G11: PA25516867 | H11: =H10 -> 25.6 | I11: =I10 -> 0 | J11: =J10 -> 21 | K11: =K10 -> 8.49 | L11: =L10 -> 0.549 | M11: 206.81 | N11: 307 | O11: =O10 -> 100.69 | P11: =P10 -> 2,30,160 | Q11: =LEFT(P11,1) -> 2 | R11: =RIGHT(P11,6) -> 30,160 | S11: =+(Q11*60+R11)/(60*60) -> 0.041711111 | T11: =+O11/S11 -> 2413.9851 | U11: =+(((N11-M11-O11)/O11)*100) -> -0.49657364 | V11: =V10 -> 20.5 | W11: =W10 -> 1.102 | X11: =X10 -> 1.094 | Y11: 334.16 | Z11: 344.16 | AA11: =AA10 -> 10.01 | AB11: =AB10 -> 22,55,230 | AC11: =LEFT(AB11,2) -> 22 | AD11: =RIGHT(AB11,6) -> 55,230 | AE11: =+(AC11*60+AD11)/(60*60) -> 0.38200833 | AF11: =+AA11/AE11 -> 26.203617 | AG11: =+(((Z11-Y11-AA11)/AA11)*100) -> -0.0999001 | AH11: =AH10 -> 21 | AI11: =AI10 -> 1.098 | AJ11: =AJ10 -> 1.088 | AK11: =Z11 -> 344.16 | AL11: 349.19 | AM11: =AM10 -> 5.009 | AN11: =AN10 -> 18,15,540 | AO11: =LEFT(AN11,2) -> 18 | AP11: =RIGHT(AN11,6) -> 15,540 | AQ11: =+(AO11*60+AP11)/(60*60) -> 0.30431667 | AR11: =+AM11/AQ11 -> 16.459828 | AS11: =+(((AL11-AK11-AM11)/AM11)*100) -> 0.41924536 | AT11: =IF(I11>=1,"NO CONFORME",IF(BK11="SIGDIFERENTES",BC11,BL11)) -> CONFORME | AU11: =B11<=C11 -> TRUE | AV11: =N11<Y11 -> TRUE | AW11: =Z11<=AK11 -> TRUE | AX11: =IF(I11>=1,"Qcorrecto",IF(AND(AY11="aceptable",AZ11="aceptable",BA11="aceptable"),"Qcorrecto","Qincorrecto")) -> Qcorrecto | AY11: =IF(AR11<$AH$6,"error",IF(AR11>$AH$6*1.1,"error","aceptable")) -> aceptable | AZ11: =IF(AF11<$V$6,"error",IF(AF11>$V$6*1.1,"error","aceptable")) -> aceptable | BA11: =IF(T11<$J$6*0.9,"error",IF(T11>$J$6,"error","aceptable")) -> aceptable | BB11: =(IF(ABS(U11)<1.05,"CONFORME",IF(ABS(AG11)<1.05,"CONFORME",IF(ABS(AS11)<2.55,"CONFORME","NO CONFORME")))) -> CONFORME | BC11: =(IF(ABS(U11)>2.05,"NO CONFORME",IF(ABS(AG11)>2.05,"NO CONFORME",IF(ABS(AS11)>5.05,"NO CONFORME","CONFORME")))) -> CONFORME | BD11: =SIGN(U11) -> -1 | BE11: =SIGN(AG11) -> -1 | BF11: =SIGN(AS11) -> 1 | BG11: =CONCATENATE(BD11,BE11,BF11) -> -1-11 | BH11: =IF(BG11="111","SI","SD") -> SD | BI11: =IF(BG11="-1-1-1","SI","SD") -> SD | BJ11: =OR(BH11="SI",BI11="SI") -> FALSE | BK11: =IF(BJ11=FALSE,"SIGDIFERENTES","SIGIGUALES") -> SIGDIFERENTES | BL11: =IF(BC11="NO CONFORME","NO CONFORME",IF(BB11="CONFORME","CONFORME","NO CONFORME")) -> CONFORME
A12: 4 | B12: =B11 -> 45920 | C12: =C11 -> 45920 | D12: =D11 -> 3 | E12: =E11 -> 8 | G12: PA25516868 | H12: =H11 -> 25.6 | I12: =I11 -> 0 | J12: =J11 -> 21 | K12: =K11 -> 8.49 | L12: =L11 -> 0.549 | M12: 246.14 | N12: 346.37 | O12: =O11 -> 100.69 | P12: =P11 -> 2,30,160 | Q12: =LEFT(P12,1) -> 2 | R12: =RIGHT(P12,6) -> 30,160 | S12: =+(Q12*60+R12)/(60*60) -> 0.041711111 | T12: =+O12/S12 -> 2413.9851 | U12: =+(((N12-M12-O12)/O12)*100) -> -0.45684775 | V12: =V11 -> 20.5 | W12: =W11 -> 1.102 | X12: =X11 -> 1.094 | Y12: 373.53 | Z12: 383.5 | AA12: =AA11 -> 10.01 | AB12: =AB11 -> 22,55,230 | AC12: =LEFT(AB12,2) -> 22 | AD12: =RIGHT(AB12,6) -> 55,230 | AE12: =+(AC12*60+AD12)/(60*60) -> 0.38200833 | AF12: =+AA12/AE12 -> 26.203617 | AG12: =+(((Z12-Y12-AA12)/AA12)*100) -> -0.3996004 | AH12: =AH11 -> 21 | AI12: =AI11 -> 1.098 | AJ12: =AJ11 -> 1.088 | AK12: =Z12 -> 383.5 | AL12: 388.51 | AM12: =AM11 -> 5.009 | AN12: =AN11 -> 18,15,540 | AO12: =LEFT(AN12,2) -> 18 | AP12: =RIGHT(AN12,6) -> 15,540 | AQ12: =+(AO12*60+AP12)/(60*60) -> 0.30431667 | AR12: =+AM12/AQ12 -> 16.459828 | AS12: =+(((AL12-AK12-AM12)/AM12)*100) -> 0.019964065 | AT12: =IF(I12>=1,"NO CONFORME",IF(BK12="SIGDIFERENTES",BC12,BL12)) -> CONFORME | AU12: =B12<=C12 -> TRUE | AV12: =N12<Y12 -> TRUE | AW12: =Z12<=AK12 -> TRUE | AX12: =IF(I12>=1,"Qcorrecto",IF(AND(AY12="aceptable",AZ12="aceptable",BA12="aceptable"),"Qcorrecto","Qincorrecto")) -> Qcorrecto | AY12: =IF(AR12<$AH$6,"error",IF(AR12>$AH$6*1.1,"error","aceptable")) -> aceptable | AZ12: =IF(AF12<$V$6,"error",IF(AF12>$V$6*1.1,"error","aceptable")) -> aceptable | BA12: =IF(T12<$J$6*0.9,"error",IF(T12>$J$6,"error","aceptable")) -> aceptable | BB12: =(IF(ABS(U12)<1.05,"CONFORME",IF(ABS(AG12)<1.05,"CONFORME",IF(ABS(AS12)<2.55,"CONFORME","NO CONFORME")))) -> CONFORME | BC12: =(IF(ABS(U12)>2.05,"NO CONFORME",IF(ABS(AG12)>2.05,"NO CONFORME",IF(ABS(AS12)>5.05,"NO CONFORME","CONFORME")))) -> CONFORME | BD12: =SIGN(U12) -> -1 | BE12: =SIGN(AG12) -> -1 | BF12: =SIGN(AS12) -> 1 | BG12: =CONCATENATE(BD12,BE12,BF12) -> -1-11 | BH12: =IF(BG12="111","SI","SD") -> SD | BI12: =IF(BG12="-1-1-1","SI","SD") -> SD | BJ12: =OR(BH12="SI",BI12="SI") -> FALSE | BK12: =IF(BJ12=FALSE,"SIGDIFERENTES","SIGIGUALES") -> SIGDIFERENTES | BL12: =IF(BC12="NO CONFORME","NO CONFORME",IF(BB12="CONFORME","CONFORME","NO CONFORME")) -> CONFORME
A13: 5 | B13: =B12 -> 45920 | C13: =C12 -> 45920 | D13: =D12 -> 3 | E13: =E12 -> 8 | G13: PA25516869 | H13: =H12 -> 25.6 | I13: =I12 -> 0 | J13: =J12 -> 21 | K13: =K12 -> 8.49 | L13: =L12 -> 0.549 | M13: 288.5 | N13: 388.1 | O13: =O12 -> 100.69 | P13: =P12 -> 2,30,160 | Q13: =LEFT(P13,1) -> 2 | R13: =RIGHT(P13,6) -> 30,160 | S13: =+(Q13*60+R13)/(60*60) -> 0.041711111 | T13: =+O13/S13 -> 2413.9851 | U13: =+(((N13-M13-O13)/O13)*100) -> -1.0825305 | V13: =V12 -> 20.5 | W13: =W12 -> 1.102 | X13: =X12 -> 1.094 | Y13: 415.15 | Z13: 425.13 | AA13: =AA12 -> 10.01 | AB13: =AB12 -> 22,55,230 | AC13: =LEFT(AB13,2) -> 22 | AD13: =RIGHT(AB13,6) -> 55,230 | AE13: =+(AC13*60+AD13)/(60*60) -> 0.38200833 | AF13: =+AA13/AE13 -> 26.203617 | AG13: =+(((Z13-Y13-AA13)/AA13)*100) -> -0.2997003 | AH13: =AH12 -> 21 | AI13: =AI12 -> 1.098 | AJ13: =AJ12 -> 1.088 | AK13: =Z13 -> 425.13 | AL13: 430.15 | AM13: =AM12 -> 5.009 | AN13: =AN12 -> 18,15,540 | AO13: =LEFT(AN13,2) -> 18 | AP13: =RIGHT(AN13,6) -> 15,540 | AQ13: =+(AO13*60+AP13)/(60*60) -> 0.30431667 | AR13: =+AM13/AQ13 -> 16.459828 | AS13: =+(((AL13-AK13-AM13)/AM13)*100) -> 0.21960471 | AT13: =IF(I13>=1,"NO CONFORME",IF(BK13="SIGDIFERENTES",BC13,BL13)) -> CONFORME | AU13: =B13<=C13 -> TRUE | AV13: =N13<Y13 -> TRUE | AW13: =Z13<=AK13 -> TRUE | AX13: =IF(I13>=1,"Qcorrecto",IF(AND(AY13="aceptable",AZ13="aceptable",BA13="aceptable"),"Qcorrecto","Qincorrecto")) -> Qcorrecto | AY13: =IF(AR13<$AH$6,"error",IF(AR13>$AH$6*1.1,"error","aceptable")) -> aceptable | AZ13: =IF(AF13<$V$6,"error",IF(AF13>$V$6*1.1,"error","aceptable")) -> aceptable | BA13: =IF(T13<$J$6*0.9,"error",IF(T13>$J$6,"error","aceptable")) -> aceptable | BB13: =(IF(ABS(U13)<1.05,"CONFORME",IF(ABS(AG13)<1.05,"CONFORME",IF(ABS(AS13)<2.55,"CONFORME","NO CONFORME")))) -> CONFORME | BC13: =(IF(ABS(U13)>2.05,"NO CONFORME",IF(ABS(AG13)>2.05,"NO CONFORME",IF(ABS(AS13)>5.05,"NO CONFORME","CONFORME")))) -> CONFORME | BD13: =SIGN(U13) -> -1 | BE13: =SIGN(AG13) -> -1 | BF13: =SIGN(AS13) -> 1 | BG13: =CONCATENATE(BD13,BE13,BF13) -> -1-11 | BH13: =IF(BG13="111","SI","SD") -> SD | BI13: =IF(BG13="-1-1-1","SI","SD") -> SD | BJ13: =OR(BH13="SI",BI13="SI") -> FALSE | BK13: =IF(BJ13=FALSE,"SIGDIFERENTES","SIGIGUALES") -> SIGDIFERENTES | BL13: =IF(BC13="NO CONFORME","NO CONFORME",IF(BB13="CONFORME","CONFORME","NO CONFORME")) -> CONFORME
A14: 6 | B14: =B13 -> 45920 | C14: =C13 -> 45920 | D14: =D13 -> 3 | E14: =E13 -> 8 | G14: PA25516870 | H14: =H13 -> 25.6 | I14: =I13 -> 0 | J14: =J13 -> 21 | K14: =K13 -> 8.49 | L14: =L13 -> 0.549 | M14: 245.27 | N14: 344.66 | O14: =O13 -> 100.69 | P14: =P13 -> 2,30,160 | Q14: =LEFT(P14,1) -> 2 | R14: =RIGHT(P14,6) -> 30,160 | S14: =+(Q14*60+R14)/(60*60) -> 0.041711111 | T14: =+O14/S14 -> 2413.9851 | U14: =+(((N14-M14-O14)/O14)*100) -> -1.2910915 | V14: =V13 -> 20.5 | W14: =W13 -> 1.102 | X14: =X13 -> 1.094 | Y14: 371.74 | Z14: 381.67 | AA14: =AA13 -> 10.01 | AB14: =AB13 -> 22,55,230 | AC14: =LEFT(AB14,2) -> 22 | AD14: =RIGHT(AB14,6) -> 55,230 | AE14: =+(AC14*60+AD14)/(60*60) -> 0.38200833 | AF14: =+AA14/AE14 -> 26.203617 | AG14: =+(((Z14-Y14-AA14)/AA14)*100) -> -0.7992008 | AH14: =AH13 -> 21 | AI14: =AI13 -> 1.098 | AJ14: =AJ13 -> 1.088 | AK14: =Z14 -> 381.67 | AL14: 386.64 | AM14: =AM13 -> 5.009 | AN14: =AN13 -> 18,15,540 | AO14: =LEFT(AN14,2) -> 18 | AP14: =RIGHT(AN14,6) -> 15,540 | AQ14: =+(AO14*60+AP14)/(60*60) -> 0.30431667 | AR14: =+AM14/AQ14 -> 16.459828 | AS14: =+(((AL14-AK14-AM14)/AM14)*100) -> -0.77859852 | AT14: =IF(I14>=1,"NO CONFORME",IF(BK14="SIGDIFERENTES",BC14,BL14)) -> CONFORME | AU14: =B14<=C14 -> TRUE | AV14: =N14<Y14 -> TRUE | AW14: =Z14<=AK14 -> TRUE | AX14: =IF(I14>=1,"Qcorrecto",IF(AND(AY14="aceptable",AZ14="aceptable",BA14="aceptable"),"Qcorrecto","Qincorrecto")) -> Qcorrecto | AY14: =IF(AR14<$AH$6,"error",IF(AR14>$AH$6*1.1,"error","aceptable")) -> aceptable | AZ14: =IF(AF14<$V$6,"error",IF(AF14>$V$6*1.1,"error","aceptable")) -> aceptable | BA14: =IF(T14<$J$6*0.9,"error",IF(T14>$J$6,"error","aceptable")) -> aceptable | BB14: =(IF(ABS(U14)<1.05,"CONFORME",IF(ABS(AG14)<1.05,"CONFORME",IF(ABS(AS14)<2.55,"CONFORME","NO CONFORME")))) -> CONFORME | BC14: =(IF(ABS(U14)>2.05,"NO CONFORME",IF(ABS(AG14)>2.05,"NO CONFORME",IF(ABS(AS14)>5.05,"NO CONFORME","CONFORME")))) -> CONFORME | BD14: =SIGN(U14) -> -1 | BE14: =SIGN(AG14) -> -1 | BF14: =SIGN(AS14) -> -1 | BG14: =CONCATENATE(BD14,BE14,BF14) -> -1-1-1 | BH14: =IF(BG14="111","SI","SD") -> SD | BI14: =IF(BG14="-1-1-1","SI","SD") -> SI | BJ14: =OR(BH14="SI",BI14="SI") -> TRUE | BK14: =IF(BJ14=FALSE,"SIGDIFERENTES","SIGIGUALES") -> SIGIGUALES | BL14: =IF(BC14="NO CONFORME","NO CONFORME",IF(BB14="CONFORME","CONFORME","NO CONFORME")) -> CONFORME
A15: 7 | B15: =B14 -> 45920 | C15: =C14 -> 45920 | D15: =D14 -> 3 | E15: =E14 -> 8 | G15: PA25516871 | H15: =H14 -> 25.6 | I15: =I14 -> 0 | J15: =J14 -> 21 | K15: =K14 -> 8.49 | L15: =L14 -> 0.549 | M15: 205.17 | N15: 305.02 | O15: =O14 -> 100.69 | P15: =P14 -> 2,30,160 | Q15: =LEFT(P15,1) -> 2 | R15: =RIGHT(P15,6) -> 30,160 | S15: =+(Q15*60+R15)/(60*60) -> 0.041711111 | T15: =+O15/S15 -> 2413.9851 | U15: =+(((N15-M15-O15)/O15)*100) -> -0.83424372 | V15: =V14 -> 20.5 | W15: =W14 -> 1.102 | X15: =X14 -> 1.094 | Y15: 332.18 | Z15: 342.18 | AA15: =AA14 -> 10.01 | AB15: =AB14 -> 22,55,230 | AC15: =LEFT(AB15,2) -> 22 | AD15: =RIGHT(AB15,6) -> 55,230 | AE15: =+(AC15*60+AD15)/(60*60) -> 0.38200833 | AF15: =+AA15/AE15 -> 26.203617 | AG15: =+(((Z15-Y15-AA15)/AA15)*100) -> -0.0999001 | AH15: =AH14 -> 21 | AI15: =AI14 -> 1.098 | AJ15: =AJ14 -> 1.088 | AK15: =Z15 -> 342.18 | AL15: 347.21 | AM15: =AM14 -> 5.009 | AN15: =AN14 -> 18,15,540 | AO15: =LEFT(AN15,2) -> 18 | AP15: =RIGHT(AN15,6) -> 15,540 | AQ15: =+(AO15*60+AP15)/(60*60) -> 0.30431667 | AR15: =+AM15/AQ15 -> 16.459828 | AS15: =+(((AL15-AK15-AM15)/AM15)*100) -> 0.41924536 | AT15: =IF(I15>=1,"NO CONFORME",IF(BK15="SIGDIFERENTES",BC15,BL15)) -> CONFORME | AU15: =B15<=C15 -> TRUE | AV15: =N15<Y15 -> TRUE | AW15: =Z15<=AK15 -> TRUE | AX15: =IF(I15>=1,"Qcorrecto",IF(AND(AY15="aceptable",AZ15="aceptable",BA15="aceptable"),"Qcorrecto","Qincorrecto")) -> Qcorrecto | AY15: =IF(AR15<$AH$6,"error",IF(AR15>$AH$6*1.1,"error","aceptable")) -> aceptable | AZ15: =IF(AF15<$V$6,"error",IF(AF15>$V$6*1.1,"error","aceptable")) -> aceptable | BA15: =IF(T15<$J$6*0.9,"error",IF(T15>$J$6,"error","aceptable")) -> aceptable | BB15: =(IF(ABS(U15)<1.05,"CONFORME",IF(ABS(AG15)<1.05,"CONFORME",IF(ABS(AS15)<2.55,"CONFORME","NO CONFORME")))) -> CONFORME | BC15: =(IF(ABS(U15)>2.05,"NO CONFORME",IF(ABS(AG15)>2.05,"NO CONFORME",IF(ABS(AS15)>5.05,"NO CONFORME","CONFORME")))) -> CONFORME | BD15: =SIGN(U15) -> -1 | BE15: =SIGN(AG15) -> -1 | BF15: =SIGN(AS15) -> 1 | BG15: =CONCATENATE(BD15,BE15,BF15) -> -1-11 | BH15: =IF(BG15="111","SI","SD") -> SD | BI15: =IF(BG15="-1-1-1","SI","SD") -> SD | BJ15: =OR(BH15="SI",BI15="SI") -> FALSE | BK15: =IF(BJ15=FALSE,"SIGDIFERENTES","SIGIGUALES") -> SIGDIFERENTES | BL15: =IF(BC15="NO CONFORME","NO CONFORME",IF(BB15="CONFORME","CONFORME","NO CONFORME")) -> CONFORME
A16: 8 | B16: =B15 -> 45920 | C16: =C15 -> 45920 | D16: =D15 -> 3 | E16: =E15 -> 8 | G16: PA25516872 | H16: =H15 -> 25.6 | I16: =I15 -> 0 | J16: =J15 -> 21 | K16: =K15 -> 8.49 | L16: =L15 -> 0.549 | M16: 209.25 | N16: 309.78 | O16: =O15 -> 100.69 | P16: =P15 -> 2,30,160 | Q16: =LEFT(P16,1) -> 2 | R16: =RIGHT(P16,6) -> 30,160 | S16: =+(Q16*60+R16)/(60*60) -> 0.041711111 | T16: =+O16/S16 -> 2413.9851 | U16: =+(((N16-M16-O16)/O16)*100) -> -0.15890357 | V16: =V15 -> 20.5 | W16: =W15 -> 1.102 | X16: =X15 -> 1.094 | Y16: 336.96 | Z16: 347.03 | AA16: =AA15 -> 10.01 | AB16: =AB15 -> 22,55,230 | AC16: =LEFT(AB16,2) -> 22 | AD16: =RIGHT(AB16,6) -> 55,230 | AE16: =+(AC16*60+AD16)/(60*60) -> 0.38200833 | AF16: =+AA16/AE16 -> 26.203617 | AG16: =+(((Z16-Y16-AA16)/AA16)*100) -> 0.5994006 | AH16: =AH15 -> 21 | AI16: =AI15 -> 1.098 | AJ16: =AJ15 -> 1.088 | AK16: =Z16 -> 347.03 | AL16: 352.03 | AM16: =AM15 -> 5.009 | AN16: =AN15 -> 18,15,540 | AO16: =LEFT(AN16,2) -> 18 | AP16: =RIGHT(AN16,6) -> 15,540 | AQ16: =+(AO16*60+AP16)/(60*60) -> 0.30431667 | AR16: =+AM16/AQ16 -> 16.459828 | AS16: =+(((AL16-AK16-AM16)/AM16)*100) -> -0.17967658 | AT16: =IF(I16>=1,"NO CONFORME",IF(BK16="SIGDIFERENTES",BC16,BL16)) -> CONFORME | AU16: =B16<=C16 -> TRUE | AV16: =N16<Y16 -> TRUE | AW16: =Z16<=AK16 -> TRUE | AX16: =IF(I16>=1,"Qcorrecto",IF(AND(AY16="aceptable",AZ16="aceptable",BA16="aceptable"),"Qcorrecto","Qincorrecto")) -> Qcorrecto | AY16: =IF(AR16<$AH$6,"error",IF(AR16>$AH$6*1.1,"error","aceptable")) -> aceptable | AZ16: =IF(AF16<$V$6,"error",IF(AF16>$V$6*1.1,"error","aceptable")) -> aceptable | BA16: =IF(T16<$J$6*0.9,"error",IF(T16>$J$6,"error","aceptable")) -> aceptable | BB16: =(IF(ABS(U16)<1.05,"CONFORME",IF(ABS(AG16)<1.05,"CONFORME",IF(ABS(AS16)<2.55,"CONFORME","NO CONFORME")))) -> CONFORME | BC16: =(IF(ABS(U16)>2.05,"NO CONFORME",IF(ABS(AG16)>2.05,"NO CONFORME",IF(ABS(AS16)>5.05,"NO CONFORME","CONFORME")))) -> CONFORME | BD16: =SIGN(U16) -> -1 | BE16: =SIGN(AG16) -> 1 | BF16: =SIGN(AS16) -> -1 | BG16: =CONCATENATE(BD16,BE16,BF16) -> -11-1 | BH16: =IF(BG16="111","SI","SD") -> SD | BI16: =IF(BG16="-1-1-1","SI","SD") -> SD | BJ16: =OR(BH16="SI",BI16="SI") -> FALSE | BK16: =IF(BJ16=FALSE,"SIGDIFERENTES","SIGIGUALES") -> SIGDIFERENTES | BL16: =IF(BC16="NO CONFORME","NO CONFORME",IF(BB16="CONFORME","CONFORME","NO CONFORME")) -> CONFORME
A17: 9 | B17: =B16 -> 45920 | C17: =C16 -> 45920 | D17: =D16 -> 3 | E17: =E16 -> 8 | G17: PA25516873 | H17: =H16 -> 25.6 | I17: =I16 -> 0 | J17: =J16 -> 21 | K17: =K16 -> 8.49 | L17: =L16 -> 0.549 | M17: 209.35 | N17: 309.4 | O17: =O16 -> 100.69 | P17: =P16 -> 2,30,160 | Q17: =LEFT(P17,1) -> 2 | R17: =RIGHT(P17,6) -> 30,160 | S17: =+(Q17*60+R17)/(60*60) -> 0.041711111 | T17: =+O17/S17 -> 2413.9851 | U17: =+(((N17-M17-O17)/O17)*100) -> -0.63561426 | V17: =V16 -> 20.5 | W17: =W16 -> 1.102 | X17: =X16 -> 1.094 | Y17: 336.54 | Z17: 346.42 | AA17: =AA16 -> 10.01 | AB17: =AB16 -> 22,55,230 | AC17: =LEFT(AB17,2) -> 22 | AD17: =RIGHT(AB17,6) -> 55,230 | AE17: =+(AC17*60+AD17)/(60*60) -> 0.38200833 | AF17: =+AA17/AE17 -> 26.203617 | AG17: =+(((Z17-Y17-AA17)/AA17)*100) -> -1.2987013 | AH17: =AH16 -> 21 | AI17: =AI16 -> 1.098 | AJ17: =AJ16 -> 1.088 | AK17: =Z17 -> 346.42 | AL17: 351.35 | AM17: =AM16 -> 5.009 | AN17: =AN16 -> 18,15,540 | AO17: =LEFT(AN17,2) -> 18 | AP17: =RIGHT(AN17,6) -> 15,540 | AQ17: =+(AO17*60+AP17)/(60*60) -> 0.30431667 | AR17: =+AM17/AQ17 -> 16.459828 | AS17: =+(((AL17-AK17-AM17)/AM17)*100) -> -1.5771611 | AT17: =IF(I17>=1,"NO CONFORME",IF(BK17="SIGDIFERENTES",BC17,BL17)) -> CONFORME | AU17: =B17<=C17 -> TRUE | AV17: =N17<Y17 -> TRUE | AW17: =Z17<=AK17 -> TRUE | AX17: =IF(I17>=1,"Qcorrecto",IF(AND(AY17="aceptable",AZ17="aceptable",BA17="aceptable"),"Qcorrecto","Qincorrecto")) -> Qcorrecto | AY17: =IF(AR17<$AH$6,"error",IF(AR17>$AH$6*1.1,"error","aceptable")) -> aceptable | AZ17: =IF(AF17<$V$6,"error",IF(AF17>$V$6*1.1,"error","aceptable")) -> aceptable | BA17: =IF(T17<$J$6*0.9,"error",IF(T17>$J$6,"error","aceptable")) -> aceptable | BB17: =(IF(ABS(U17)<1.05,"CONFORME",IF(ABS(AG17)<1.05,"CONFORME",IF(ABS(AS17)<2.55,"CONFORME","NO CONFORME")))) -> CONFORME | BC17: =(IF(ABS(U17)>2.05,"NO CONFORME",IF(ABS(AG17)>2.05,"NO CONFORME",IF(ABS(AS17)>5.05,"NO CONFORME","CONFORME")))) -> CONFORME | BD17: =SIGN(U17) -> -1 | BE17: =SIGN(AG17) -> -1 | BF17: =SIGN(AS17) -> -1 | BG17: =CONCATENATE(BD17,BE17,BF17) -> -1-1-1 | BH17: =IF(BG17="111","SI","SD") -> SD | BI17: =IF(BG17="-1-1-1","SI","SD") -> SI | BJ17: =OR(BH17="SI",BI17="SI") -> TRUE | BK17: =IF(BJ17=FALSE,"SIGDIFERENTES","SIGIGUALES") -> SIGIGUALES | BL17: =IF(BC17="NO CONFORME","NO CONFORME",IF(BB17="CONFORME","CONFORME","NO CONFORME")) -> CONFORME
A18: 10 | B18: =B17 -> 45920 | C18: =C17 -> 45920 | D18: =D17 -> 3 | E18: =E17 -> 8 | G18: PA25516874 | H18: =H17 -> 25.6 | I18: =I17 -> 0 | J18: =J17 -> 21 | K18: =K17 -> 8.49 | L18: =L17 -> 0.549 | M18: 208.55 | N18: 308.29 | O18: =O17 -> 100.69 | P18: =P17 -> 2,30,160 | Q18: =LEFT(P18,1) -> 2 | R18: =RIGHT(P18,6) -> 30,160 | S18: =+(Q18*60+R18)/(60*60) -> 0.041711111 | T18: =+O18/S18 -> 2413.9851 | U18: =+(((N18-M18-O18)/O18)*100) -> -0.94348992 | V18: =V17 -> 20.5 | W18: =W17 -> 1.102 | X18: =X17 -> 1.094 | Y18: 335.35 | Z18: 345.28 | AA18: =AA17 -> 10.01 | AB18: =AB17 -> 22,55,230 | AC18: =LEFT(AB18,2) -> 22 | AD18: =RIGHT(AB18,6) -> 55,230 | AE18: =+(AC18*60+AD18)/(60*60) -> 0.38200833 | AF18: =+AA18/AE18 -> 26.203617 | AG18: =+(((Z18-Y18-AA18)/AA18)*100) -> -0.7992008 | AH18: =AH17 -> 21 | AI18: =AI17 -> 1.098 | AJ18: =AJ17 -> 1.088 | AK18: =Z18 -> 345.28 | AL18: 350.3 | AM18: =AM17 -> 5.009 | AN18: =AN17 -> 18,15,540 | AO18: =LEFT(AN18,2) -> 18 | AP18: =RIGHT(AN18,6) -> 15,540 | AQ18: =+(AO18*60+AP18)/(60*60) -> 0.30431667 | AR18: =+AM18/AQ18 -> 16.459828 | AS18: =+(((AL18-AK18-AM18)/AM18)*100) -> 0.21960471 | AT18: =IF(I18>=1,"NO CONFORME",IF(BK18="SIGDIFERENTES",BC18,BL18)) -> CONFORME | AU18: =B18<=C18 -> TRUE | AV18: =N18<Y18 -> TRUE | AW18: =Z18<=AK18 -> TRUE | AX18: =IF(I18>=1,"Qcorrecto",IF(AND(AY18="aceptable",AZ18="aceptable",BA18="aceptable"),"Qcorrecto","Qincorrecto")) -> Qcorrecto | AY18: =IF(AR18<$AH$6,"error",IF(AR18>$AH$6*1.1,"error","aceptable")) -> aceptable | AZ18: =IF(AF18<$V$6,"error",IF(AF18>$V$6*1.1,"error","aceptable")) -> aceptable | BA18: =IF(T18<$J$6*0.9,"error",IF(T18>$J$6,"error","aceptable")) -> aceptable | BB18: =(IF(ABS(U18)<1.05,"CONFORME",IF(ABS(AG18)<1.05,"CONFORME",IF(ABS(AS18)<2.55,"CONFORME","NO CONFORME")))) -> CONFORME | BC18: =(IF(ABS(U18)>2.05,"NO CONFORME",IF(ABS(AG18)>2.05,"NO CONFORME",IF(ABS(AS18)>5.05,"NO CONFORME","CONFORME")))) -> CONFORME | BD18: =SIGN(U18) -> -1 | BE18: =SIGN(AG18) -> -1 | BF18: =SIGN(AS18) -> 1 | BG18: =CONCATENATE(BD18,BE18,BF18) -> -1-11 | BH18: =IF(BG18="111","SI","SD") -> SD | BI18: =IF(BG18="-1-1-1","SI","SD") -> SD | BJ18: =OR(BH18="SI",BI18="SI") -> FALSE | BK18: =IF(BJ18=FALSE,"SIGDIFERENTES","SIGIGUALES") -> SIGDIFERENTES | BL18: =IF(BC18="NO CONFORME","NO CONFORME",IF(BB18="CONFORME","CONFORME","NO CONFORME")) -> CONFORME
A19: 11 | B19: =B18 -> 45920 | C19: =C18 -> 45920 | D19: =D18 -> 3 | E19: =E18 -> 8 | G19: PA25516875 | H19: =H18 -> 25.6 | I19: =I18 -> 0 | J19: =J18 -> 21 | K19: =K18 -> 8.49 | L19: =L18 -> 0.549 | M19: 208.27 | N19: 308.79 | O19: =O18 -> 100.69 | P19: =P18 -> 2,30,160 | Q19: =LEFT(P19,1) -> 2 | R19: =RIGHT(P19,6) -> 30,160 | S19: =+(Q19*60+R19)/(60*60) -> 0.041711111 | T19: =+O19/S19 -> 2413.9851 | U19: =+(((N19-M19-O19)/O19)*100) -> -0.16883504 | V19: =V18 -> 20.5 | W19: =W18 -> 1.102 | X19: =X18 -> 1.094 | Y19: 335.94 | Z19: 345.89 | AA19: =AA18 -> 10.01 | AB19: =AB18 -> 22,55,230 | AC19: =LEFT(AB19,2) -> 22 | AD19: =RIGHT(AB19,6) -> 55,230 | AE19: =+(AC19*60+AD19)/(60*60) -> 0.38200833 | AF19: =+AA19/AE19 -> 26.203617 | AG19: =+(((Z19-Y19-AA19)/AA19)*100) -> -0.5994006 | AH19: =AH18 -> 21 | AI19: =AI18 -> 1.098 | AJ19: =AJ18 -> 1.088 | AK19: =Z19 -> 345.89 | AL19: 350.88 | AM19: =AM18 -> 5.009 | AN19: =AN18 -> 18,15,540 | AO19: =LEFT(AN19,2) -> 18 | AP19: =RIGHT(AN19,6) -> 15,540 | AQ19: =+(AO19*60+AP19)/(60*60) -> 0.30431667 | AR19: =+AM19/AQ19 -> 16.459828 | AS19: =+(((AL19-AK19-AM19)/AM19)*100) -> -0.37931723 | AT19: =IF(I19>=1,"NO CONFORME",IF(BK19="SIGDIFERENTES",BC19,BL19)) -> CONFORME | AU19: =B19<=C19 -> TRUE | AV19: =N19<Y19 -> TRUE | AW19: =Z19<=AK19 -> TRUE | AX19: =IF(I19>=1,"Qcorrecto",IF(AND(AY19="aceptable",AZ19="aceptable",BA19="aceptable"),"Qcorrecto","Qincorrecto")) -> Qcorrecto | AY19: =IF(AR19<$AH$6,"error",IF(AR19>$AH$6*1.1,"error","aceptable")) -> aceptable | AZ19: =IF(AF19<$V$6,"error",IF(AF19>$V$6*1.1,"error","aceptable")) -> aceptable | BA19: =IF(T19<$J$6*0.9,"error",IF(T19>$J$6,"error","aceptable")) -> aceptable | BB19: =(IF(ABS(U19)<1.05,"CONFORME",IF(ABS(AG19)<1.05,"CONFORME",IF(ABS(AS19)<2.55,"CONFORME","NO CONFORME")))) -> CONFORME | BC19: =(IF(ABS(U19)>2.05,"NO CONFORME",IF(ABS(AG19)>2.05,"NO CONFORME",IF(ABS(AS19)>5.05,"NO CONFORME","CONFORME")))) -> CONFORME | BD19: =SIGN(U19) -> -1 | BE19: =SIGN(AG19) -> -1 | BF19: =SIGN(AS19) -> -1 | BG19: =CONCATENATE(BD19,BE19,BF19) -> -1-1-1 | BH19: =IF(BG19="111","SI","SD") -> SD | BI19: =IF(BG19="-1-1-1","SI","SD") -> SI | BJ19: =OR(BH19="SI",BI19="SI") -> TRUE | BK19: =IF(BJ19=FALSE,"SIGDIFERENTES","SIGIGUALES") -> SIGIGUALES | BL19: =IF(BC19="NO CONFORME","NO CONFORME",IF(BB19="CONFORME","CONFORME","NO CONFORME")) -> CONFORME
A20: 12 | B20: =B19 -> 45920 | C20: =C19 -> 45920 | D20: =D19 -> 3 | E20: =E19 -> 8 | G20: PA25516876 | H20: =H19 -> 25.6 | I20: =I19 -> 0 | J20: =J19 -> 21 | K20: =K19 -> 8.49 | L20: =L19 -> 0.549 | M20: 247.8 | N20: 347.95 | O20: =O19 -> 100.69 | P20: =P19 -> 2,30,160 | Q20: =LEFT(P20,1) -> 2 | R20: =RIGHT(P20,6) -> 30,160 | S20: =+(Q20*60+R20)/(60*60) -> 0.041711111 | T20: =+O20/S20 -> 2413.9851 | U20: =+(((N20-M20-O20)/O20)*100) -> -0.53629953 | V20: =V19 -> 20.5 | W20: =W19 -> 1.102 | X20: =X19 -> 1.094 | Y20: 375.03 | Z20: 384.95 | AA20: =AA19 -> 10.01 | AB20: =AB19 -> 22,55,230 | AC20: =LEFT(AB20,2) -> 22 | AD20: =RIGHT(AB20,6) -> 55,230 | AE20: =+(AC20*60+AD20)/(60*60) -> 0.38200833 | AF20: =+AA20/AE20 -> 26.203617 | AG20: =+(((Z20-Y20-AA20)/AA20)*100) -> -0.8991009 | AH20: =AH19 -> 21 | AI20: =AI19 -> 1.098 | AJ20: =AJ19 -> 1.088 | AK20: =Z20 -> 384.95 | AL20: 389.9 | AM20: =AM19 -> 5.009 | AN20: =AN19 -> 18,15,540 | AO20: =LEFT(AN20,2) -> 18 | AP20: =RIGHT(AN20,6) -> 15,540 | AQ20: =+(AO20*60+AP20)/(60*60) -> 0.30431667 | AR20: =+AM20/AQ20 -> 16.459828 | AS20: =+(((AL20-AK20-AM20)/AM20)*100) -> -1.1778798 | AT20: =IF(I20>=1,"NO CONFORME",IF(BK20="SIGDIFERENTES",BC20,BL20)) -> CONFORME | AU20: =B20<=C20 -> TRUE | AV20: =N20<Y20 -> TRUE | AW20: =Z20<=AK20 -> TRUE | AX20: =IF(I20>=1,"Qcorrecto",IF(AND(AY20="aceptable",AZ20="aceptable",BA20="aceptable"),"Qcorrecto","Qincorrecto")) -> Qcorrecto | AY20: =IF(AR20<$AH$6,"error",IF(AR20>$AH$6*1.1,"error","aceptable")) -> aceptable | AZ20: =IF(AF20<$V$6,"error",IF(AF20>$V$6*1.1,"error","aceptable")) -> aceptable | BA20: =IF(T20<$J$6*0.9,"error",IF(T20>$J$6,"error","aceptable")) -> aceptable | BB20: =(IF(ABS(U20)<1.05,"CONFORME",IF(ABS(AG20)<1.05,"CONFORME",IF(ABS(AS20)<2.55,"CONFORME","NO CONFORME")))) -> CONFORME | BC20: =(IF(ABS(U20)>2.05,"NO CONFORME",IF(ABS(AG20)>2.05,"NO CONFORME",IF(ABS(AS20)>5.05,"NO CONFORME","CONFORME")))) -> CONFORME | BD20: =SIGN(U20) -> -1 | BE20: =SIGN(AG20) -> -1 | BF20: =SIGN(AS20) -> -1 | BG20: =CONCATENATE(BD20,BE20,BF20) -> -1-1-1 | BH20: =IF(BG20="111","SI","SD") -> SD | BI20: =IF(BG20="-1-1-1","SI","SD") -> SI | BJ20: =OR(BH20="SI",BI20="SI") -> TRUE | BK20: =IF(BJ20=FALSE,"SIGDIFERENTES","SIGIGUALES") -> SIGIGUALES | BL20: =IF(BC20="NO CONFORME","NO CONFORME",IF(BB20="CONFORME","CONFORME","NO CONFORME")) -> CONFORME
A21: 13 | B21: =B20 -> 45920 | C21: =C20 -> 45920 | D21: =D20 -> 3 | E21: =E20 -> 8 | G21: PA25516877 | H21: =H20 -> 25.6 | I21: =I20 -> 0 | J21: =J20 -> 21 | K21: =K20 -> 8.49 | L21: =L20 -> 0.549 | M21: 248.29 | N21: 348.55 | O21: =O20 -> 100.69 | P21: =P20 -> 2,30,160 | Q21: =LEFT(P21,1) -> 2 | R21: =RIGHT(P21,6) -> 30,160 | S21: =+(Q21*60+R21)/(60*60) -> 0.041711111 | T21: =+O21/S21 -> 2413.9851 | U21: =+(((N21-M21-O21)/O21)*100) -> -0.42705333 | V21: =V20 -> 20.5 | W21: =W20 -> 1.102 | X21: =X20 -> 1.094 | Y21: 375.53 | Z21: 385.41 | AA21: =AA20 -> 10.01 | AB21: =AB20 -> 22,55,230 | AC21: =LEFT(AB21,2) -> 22 | AD21: =RIGHT(AB21,6) -> 55,230 | AE21: =+(AC21*60+AD21)/(60*60) -> 0.38200833 | AF21: =+AA21/AE21 -> 26.203617 | AG21: =+(((Z21-Y21-AA21)/AA21)*100) -> -1.2987013 | AH21: =AH20 -> 21 | AI21: =AI20 -> 1.098 | AJ21: =AJ20 -> 1.088 | AK21: =Z21 -> 385.41 | AL21: 390.37 | AM21: =AM20 -> 5.009 | AN21: =AN20 -> 18,15,540 | AO21: =LEFT(AN21,2) -> 18 | AP21: =RIGHT(AN21,6) -> 15,540 | AQ21: =+(AO21*60+AP21)/(60*60) -> 0.30431667 | AR21: =+AM21/AQ21 -> 16.459828 | AS21: =+(((AL21-AK21-AM21)/AM21)*100) -> -0.97823917 | AT21: =IF(I21>=1,"NO CONFORME",IF(BK21="SIGDIFERENTES",BC21,BL21)) -> CONFORME | AU21: =B21<=C21 -> TRUE | AV21: =N21<Y21 -> TRUE | AW21: =Z21<=AK21 -> TRUE | AX21: =IF(I21>=1,"Qcorrecto",IF(AND(AY21="aceptable",AZ21="aceptable",BA21="aceptable"),"Qcorrecto","Qincorrecto")) -> Qcorrecto | AY21: =IF(AR21<$AH$6,"error",IF(AR21>$AH$6*1.1,"error","aceptable")) -> aceptable | AZ21: =IF(AF21<$V$6,"error",IF(AF21>$V$6*1.1,"error","aceptable")) -> aceptable | BA21: =IF(T21<$J$6*0.9,"error",IF(T21>$J$6,"error","aceptable")) -> aceptable | BB21: =(IF(ABS(U21)<1.05,"CONFORME",IF(ABS(AG21)<1.05,"CONFORME",IF(ABS(AS21)<2.55,"CONFORME","NO CONFORME")))) -> CONFORME | BC21: =(IF(ABS(U21)>2.05,"NO CONFORME",IF(ABS(AG21)>2.05,"NO CONFORME",IF(ABS(AS21)>5.05,"NO CONFORME","CONFORME")))) -> CONFORME | BD21: =SIGN(U21) -> -1 | BE21: =SIGN(AG21) -> -1 | BF21: =SIGN(AS21) -> -1 | BG21: =CONCATENATE(BD21,BE21,BF21) -> -1-1-1 | BH21: =IF(BG21="111","SI","SD") -> SD | BI21: =IF(BG21="-1-1-1","SI","SD") -> SI | BJ21: =OR(BH21="SI",BI21="SI") -> TRUE | BK21: =IF(BJ21=FALSE,"SIGDIFERENTES","SIGIGUALES") -> SIGIGUALES | BL21: =IF(BC21="NO CONFORME","NO CONFORME",IF(BB21="CONFORME","CONFORME","NO CONFORME")) -> CONFORME
... A24: 16 | B24: =B23 -> 45920 | C24: =C23 -> 45920 | D24: =D23 -> 3 | E24: =E23 -> 8 | G24: PA25516880 | H24: =H23 -> 25.6 | I24: =I23 -> 0 | J24: =J23 -> 21 | K24: =K23 -> 8.49 | L24: =L23 -> 0.549 | M24: 206.75 | N24: 306.42 | O24: =O23 -> 100.69 | P24: =P23 -> 2,30,160 | Q24: =LEFT(P24,1) -> 2 | R24: =RIGHT(P24,6) -> 30,160 | S24: =+(Q24*60+R24)/(60*60) -> 0.041711111 | T24: =+O24/S24 -> 2413.9851 | U24: =+(((N24-M24-O24)/O24)*100) -> -1.0130102 | V24: =V23 -> 20.5 | W24: =W23 -> 1.102 | X24: =X23 -> 1.094 | Y24: 333.48 | Z24: 343.43 | AA24: =AA23 -> 10.01 | AB24: =AB23 -> 22,55,230 | AC24: =LEFT(AB24,2) -> 22 | AD24: =RIGHT(AB24,6) -> 55,230 | AE24: =+(AC24*60+AD24)/(60*60) -> 0.38200833 | AF24: =+AA24/AE24 -> 26.203617 | AG24: =+(((Z24-Y24-AA24)/AA24)*100) -> -0.5994006 | AH24: =AH23 -> 21 | AI24: =AI23 -> 1.098 | AJ24: =AJ23 -> 1.088 | AK24: =Z24 -> 343.43 | AL24: 348.44 | AM24: =AM23 -> 5.009 | AN24: =AN23 -> 18,15,540 | AO24: =LEFT(AN24,2) -> 18 | AP24: =RIGHT(AN24,6) -> 15,540 | AQ24: =+(AO24*60+AP24)/(60*60) -> 0.30431667 | AR24: =+AM24/AQ24 -> 16.459828 | AS24: =+(((AL24-AK24-AM24)/AM24)*100) -> 0.019964065 | AT24: =IF(I24>=1,"NO CONFORME",IF(BK24="SIGDIFERENTES",BC24,BL24)) -> CONFORME | AU24: =B24<=C24 -> TRUE | AV24: =N24<Y24 -> TRUE | AW24: =Z24<=AK24 -> TRUE | AX24: =IF(I24>=1,"Qcorrecto",IF(AND(AY24="aceptable",AZ24="aceptable",BA24="aceptable"),"Qcorrecto","Qincorrecto")) -> Qcorrecto | AY24: =IF(AR24<$AH$6,"error",IF(AR24>$AH$6*1.1,"error","aceptable")) -> aceptable | AZ24: =IF(AF24<$V$6,"error",IF(AF24>$V$6*1.1,"error","aceptable")) -> aceptable | BA24: =IF(T24<$J$6*0.9,"error",IF(T24>$J$6,"error","aceptable")) -> aceptable | BB24: =(IF(ABS(U24)<1.05,"CONFORME",IF(ABS(AG24)<1.05,"CONFORME",IF(ABS(AS24)<2.55,"CONFORME","NO CONFORME")))) -> CONFORME | BC24: =(IF(ABS(U24)>2.05,"NO CONFORME",IF(ABS(AG24)>2.05,"NO CONFORME",IF(ABS(AS24)>5.05,"NO CONFORME","CONFORME")))) -> CONFORME | BD24: =SIGN(U24) -> -1 | BE24: =SIGN(AG24) -> -1 | BF24: =SIGN(AS24) -> 1 | BG24: =CONCATENATE(BD24,BE24,BF24) -> -1-11 | BH24: =IF(BG24="111","SI","SD") -> SD | BI24: =IF(BG24="-1-1-1","SI","SD") -> SD | BJ24: =OR(BH24="SI",BI24="SI") -> FALSE | BK24: =IF(BJ24=FALSE,"SIGDIFERENTES","SIGIGUALES") -> SIGDIFERENTES | BL24: =IF(BC24="NO CONFORME","NO CONFORME",IF(BB24="CONFORME","CONFORME","NO CONFORME")) -> CONFORME
A25: 17 | B25: =B24 -> 45920 | C25: =C24 -> 45920 | D25: =D24 -> 3 | E25: =E24 -> 8 | G25: PA25516881 | H25: =H24 -> 25.6 | I25: =I24 -> 0 | J25: 20.5 | K25: 8.487 | L25: 0.592 | M25: 100.7 | N25: 199.56 | O25: 100.31 | P25: 2,30,140 | Q25: =LEFT(P25,1) -> 2 | R25: =RIGHT(P25,6) -> 30,140 | S25: =+(Q25*60+R25)/(60*60) -> 0.041705556 | T25: =+O25/S25 -> 2405.1952 | U25: =+(((N25-M25-O25)/O25)*100) -> -1.4455189 | V25: 20.7 | W25: 1.095 | X25: 1.086 | Y25: 224.84 | Z25: 234.76 | AA25: 10.008 | AB25: 22,32,060 | AC25: =LEFT(AB25,2) -> 22 | AD25: =RIGHT(AB25,6) -> 32,060 | AE25: =+(AC25*60+AD25)/(60*60) -> 0.37557222 | AF25: =+AA25/AE25 -> 26.647338 | AG25: =+(((Z25-Y25-AA25)/AA25)*100) -> -0.87929656 | AH25: 21.3 | AI25: 1.096 | AJ25: 1.087 | AK25: =Z25 -> 234.76 | AL25: 239.72 | AM25: 5.005 | AN25: 18,09,850 | AO25: =LEFT(AN25,2) -> 18 | AP25: =RIGHT(AN25,6) -> 09,850 | AQ25: =+(AO25*60+AP25)/(60*60) -> 0.30273611 | AR25: =+AM25/AQ25 -> 16.53255 | AS25: =+(((AL25-AK25-AM25)/AM25)*100) -> -0.8991009 | AT25: =IF(I25>=1,"NO CONFORME",IF(BK25="SIGDIFERENTES",BC25,BL25)) -> CONFORME | AU25: =B25<=C25 -> TRUE | AV25: =N25<Y25 -> TRUE | AW25: =Z25<=AK25 -> TRUE | AX25: =IF(I25>=1,"Qcorrecto",IF(AND(AY25="aceptable",AZ25="aceptable",BA25="aceptable"),"Qcorrecto","Qincorrecto")) -> Qcorrecto | AY25: =IF(AR25<$AH$6,"error",IF(AR25>$AH$6*1.1,"error","aceptable")) -> aceptable | AZ25: =IF(AF25<$V$6,"error",IF(AF25>$V$6*1.1,"error","aceptable")) -> aceptable | BA25: =IF(T25<$J$6*0.9,"error",IF(T25>$J$6,"error","aceptable")) -> aceptable | BB25: =(IF(ABS(U25)<1.05,"CONFORME",IF(ABS(AG25)<1.05,"CONFORME",IF(ABS(AS25)<2.55,"CONFORME","NO CONFORME")))) -> CONFORME | BC25: =(IF(ABS(U25)>2.05,"NO CONFORME",IF(ABS(AG25)>2.05,"NO CONFORME",IF(ABS(AS25)>5.05,"NO CONFORME","CONFORME")))) -> CONFORME | BD25: =SIGN(U25) -> -1 | BE25: =SIGN(AG25) -> -1 | BF25: =SIGN(AS25) -> -1 | BG25: =CONCATENATE(BD25,BE25,BF25) -> -1-1-1 | BH25: =IF(BG25="111","SI","SD") -> SD | BI25: =IF(BG25="-1-1-1","SI","SD") -> SI | BJ25: =OR(BH25="SI",BI25="SI") -> TRUE | BK25: =IF(BJ25=FALSE,"SIGDIFERENTES","SIGIGUALES") -> SIGIGUALES | BL25: =IF(BC25="NO CONFORME","NO CONFORME",IF(BB25="CONFORME","CONFORME","NO CONFORME")) -> CONFORME
A26: 18 | B26: =B25 -> 45920 | C26: =C25 -> 45920 | D26: =D25 -> 3 | E26: =E25 -> 8 | G26: PA25516882 | H26: =H25 -> 25.6 | I26: =I25 -> 0 | J26: =J25 -> 20.5 | K26: =K25 -> 8.487 | L26: =L25 -> 0.592 | M26: 141.29 | N26: 240.55 | O26: =O25 -> 100.31 | P26: =P25 -> 2,30,140 | Q26: =LEFT(P26,1) -> 2 | R26: =RIGHT(P26,6) -> 30,140 | S26: =+(Q26*60+R26)/(60*60) -> 0.041705556 | T26: =+O26/S26 -> 2405.1952 | U26: =+(((N26-M26-O26)/O26)*100) -> -1.0467551 | V26: =V25 -> 20.7 | W26: =W25 -> 1.095 | X26: =X25 -> 1.086 | Y26: 265.99 | Z26: 275.99 | AA26: =AA25 -> 10.008 | AB26: =AB25 -> 22,32,060 | AC26: =LEFT(AB26,2) -> 22 | AD26: =RIGHT(AB26,6) -> 32,060 | AE26: =+(AC26*60+AD26)/(60*60) -> 0.37557222 | AF26: =+AA26/AE26 -> 26.647338 | AG26: =+(((Z26-Y26-AA26)/AA26)*100) -> -0.079936051 | AH26: =AH25 -> 21.3 | AI26: =AI25 -> 1.096 | AJ26: =AJ25 -> 1.087 | AK26: =Z26 -> 275.99 | AL26: 281.02 | AM26: =AM25 -> 5.005 | AN26: =AN25 -> 18,09,850 | AO26: =LEFT(AN26,2) -> 18 | AP26: =RIGHT(AN26,6) -> 09,850 | AQ26: =+(AO26*60+AP26)/(60*60) -> 0.30273611 | AR26: =+AM26/AQ26 -> 16.53255 | AS26: =+(((AL26-AK26-AM26)/AM26)*100) -> 0.4995005 | AT26: =IF(I26>=1,"NO CONFORME",IF(BK26="SIGDIFERENTES",BC26,BL26)) -> CONFORME | AU26: =B26<=C26 -> TRUE | AV26: =N26<Y26 -> TRUE | AW26: =Z26<=AK26 -> TRUE | AX26: =IF(I26>=1,"Qcorrecto",IF(AND(AY26="aceptable",AZ26="aceptable",BA26="aceptable"),"Qcorrecto","Qincorrecto")) -> Qcorrecto | AY26: =IF(AR26<$AH$6,"error",IF(AR26>$AH$6*1.1,"error","aceptable")) -> aceptable | AZ26: =IF(AF26<$V$6,"error",IF(AF26>$V$6*1.1,"error","aceptable")) -> aceptable | BA26: =IF(T26<$J$6*0.9,"error",IF(T26>$J$6,"error","aceptable")) -> aceptable | BB26: =(IF(ABS(U26)<1.05,"CONFORME",IF(ABS(AG26)<1.05,"CONFORME",IF(ABS(AS26)<2.55,"CONFORME","NO CONFORME")))) -> CONFORME | BC26: =(IF(ABS(U26)>2.05,"NO CONFORME",IF(ABS(AG26)>2.05,"NO CONFORME",IF(ABS(AS26)>5.05,"NO CONFORME","CONFORME")))) -> CONFORME | BD26: =SIGN(U26) -> -1 | BE26: =SIGN(AG26) -> -1 | BF26: =SIGN(AS26) -> 1 | BG26: =CONCATENATE(BD26,BE26,BF26) -> -1-11 | BH26: =IF(BG26="111","SI","SD") -> SD | BI26: =IF(BG26="-1-1-1","SI","SD") -> SD | BJ26: =OR(BH26="SI",BI26="SI") -> FALSE | BK26: =IF(BJ26=FALSE,"SIGDIFERENTES","SIGIGUALES") -> SIGDIFERENTES | BL26: =IF(BC26="NO CONFORME","NO CONFORME",IF(BB26="CONFORME","CONFORME","NO CONFORME")) -> CONFORME
A27: 19 | B27: =B26 -> 45920 | C27: =C26 -> 45920 | D27: =D26 -> 3 | E27: =E26 -> 8 | G27: PA25516883 | H27: =H26 -> 25.6 | I27: =I26 -> 0 | J27: =J26 -> 20.5 | K27: =K26 -> 8.487 | L27: =L26 -> 0.592 | M27: 103.19 | N27: 202.51 | O27: =O26 -> 100.31 | P27: =P26 -> 2,30,140 | Q27: =LEFT(P27,1) -> 2 | R27: =RIGHT(P27,6) -> 30,140 | S27: =+(Q27*60+R27)/(60*60) -> 0.041705556 | T27: =+O27/S27 -> 2405.1952 | U27: =+(((N27-M27-O27)/O27)*100) -> -0.98694048 | V27: =V26 -> 20.7 | W27: =W26 -> 1.095 | X27: =X26 -> 1.086 | Y27: 227.95 | Z27: 237.9 | AA27: =AA26 -> 10.008 | AB27: =AB26 -> 22,32,060 | AC27: =LEFT(AB27,2) -> 22 | AD27: =RIGHT(AB27,6) -> 32,060 | AE27: =+(AC27*60+AD27)/(60*60) -> 0.37557222 | AF27: =+AA27/AE27 -> 26.647338 | AG27: =+(((Z27-Y27-AA27)/AA27)*100) -> -0.57953637 | AH27: =AH26 -> 21.3 | AI27: =AI26 -> 1.096 | AJ27: =AJ26 -> 1.087 | AK27: =Z27 -> 237.9 | AL27: 242.94 | AM27: =AM26 -> 5.005 | AN27: =AN26 -> 18,09,850 | AO27: =LEFT(AN27,2) -> 18 | AP27: =RIGHT(AN27,6) -> 09,850 | AQ27: =+(AO27*60+AP27)/(60*60) -> 0.30273611 | AR27: =+AM27/AQ27 -> 16.53255 | AS27: =+(((AL27-AK27-AM27)/AM27)*100) -> 0.6993007 | AT27: =IF(I27>=1,"NO CONFORME",IF(BK27="SIGDIFERENTES",BC27,BL27)) -> CONFORME | AU27: =B27<=C27 -> TRUE | AV27: =N27<Y27 -> TRUE | AW27: =Z27<=AK27 -> TRUE | AX27: =IF(I27>=1,"Qcorrecto",IF(AND(AY27="aceptable",AZ27="aceptable",BA27="aceptable"),"Qcorrecto","Qincorrecto")) -> Qcorrecto | AY27: =IF(AR27<$AH$6,"error",IF(AR27>$AH$6*1.1,"error","aceptable")) -> aceptable | AZ27: =IF(AF27<$V$6,"error",IF(AF27>$V$6*1.1,"error","aceptable")) -> aceptable | BA27: =IF(T27<$J$6*0.9,"error",IF(T27>$J$6,"error","aceptable")) -> aceptable | BB27: =(IF(ABS(U27)<1.05,"CONFORME",IF(ABS(AG27)<1.05,"CONFORME",IF(ABS(AS27)<2.55,"CONFORME","NO CONFORME")))) -> CONFORME | BC27: =(IF(ABS(U27)>2.05,"NO CONFORME",IF(ABS(AG27)>2.05,"NO CONFORME",IF(ABS(AS27)>5.05,"NO CONFORME","CONFORME")))) -> CONFORME | BD27: =SIGN(U27) -> -1 | BE27: =SIGN(AG27) -> -1 | BF27: =SIGN(AS27) -> 1 | BG27: =CONCATENATE(BD27,BE27,BF27) -> -1-11 | BH27: =IF(BG27="111","SI","SD") -> SD | BI27: =IF(BG27="-1-1-1","SI","SD") -> SD | BJ27: =OR(BH27="SI",BI27="SI") -> FALSE | BK27: =IF(BJ27=FALSE,"SIGDIFERENTES","SIGIGUALES") -> SIGDIFERENTES | BL27: =IF(BC27="NO CONFORME","NO CONFORME",IF(BB27="CONFORME","CONFORME","NO CONFORME")) -> CONFORME
A28: 20 | B28: =B27 -> 45920 | C28: =C27 -> 45920 | D28: =D27 -> 3 | E28: =E27 -> 8 | G28: PA25516884 | H28: =H27 -> 25.6 | I28: =I27 -> 0 | J28: =J27 -> 20.5 | K28: =K27 -> 8.487 | L28: =L27 -> 0.592 | M28: 140.7 | N28: 240.36 | O28: =O27 -> 100.31 | P28: =P27 -> 2,30,140 | Q28: =LEFT(P28,1) -> 2 | R28: =RIGHT(P28,6) -> 30,140 | S28: =+(Q28*60+R28)/(60*60) -> 0.041705556 | T28: =+O28/S28 -> 2405.1952 | U28: =+(((N28-M28-O28)/O28)*100) -> -0.64799123 | V28: =V27 -> 20.7 | W28: =W27 -> 1.095 | X28: =X27 -> 1.086 | Y28: 265.75 | Z28: 275.69 | AA28: =AA27 -> 10.008 | AB28: =AB27 -> 22,32,060 | AC28: =LEFT(AB28,2) -> 22 | AD28: =RIGHT(AB28,6) -> 32,060 | AE28: =+(AC28*60+AD28)/(60*60) -> 0.37557222 | AF28: =+AA28/AE28 -> 26.647338 | AG28: =+(((Z28-Y28-AA28)/AA28)*100) -> -0.67945643 | AH28: =AH27 -> 21.3 | AI28: =AI27 -> 1.096 | AJ28: =AJ27 -> 1.087 | AK28: =Z28 -> 275.69 | AL28: 280.68 | AM28: =AM27 -> 5.005 | AN28: =AN27 -> 18,09,850 | AO28: =LEFT(AN28,2) -> 18 | AP28: =RIGHT(AN28,6) -> 09,850 | AQ28: =+(AO28*60+AP28)/(60*60) -> 0.30273611 | AR28: =+AM28/AQ28 -> 16.53255 | AS28: =+(((AL28-AK28-AM28)/AM28)*100) -> -0.2997003 | AT28: =IF(I28>=1,"NO CONFORME",IF(BK28="SIGDIFERENTES",BC28,BL28)) -> CONFORME | AU28: =B28<=C28 -> TRUE | AV28: =N28<Y28 -> TRUE | AW28: =Z28<=AK28 -> TRUE | AX28: =IF(I28>=1,"Qcorrecto",IF(AND(AY28="aceptable",AZ28="aceptable",BA28="aceptable"),"Qcorrecto","Qincorrecto")) -> Qcorrecto | AY28: =IF(AR28<$AH$6,"error",IF(AR28>$AH$6*1.1,"error","aceptable")) -> aceptable | AZ28: =IF(AF28<$V$6,"error",IF(AF28>$V$6*1.1,"error","aceptable")) -> aceptable | BA28: =IF(T28<$J$6*0.9,"error",IF(T28>$J$6,"error","aceptable")) -> aceptable | BB28: =(IF(ABS(U28)<1.05,"CONFORME",IF(ABS(AG28)<1.05,"CONFORME",IF(ABS(AS28)<2.55,"CONFORME","NO CONFORME")))) -> CONFORME | BC28: =(IF(ABS(U28)>2.05,"NO CONFORME",IF(ABS(AG28)>2.05,"NO CONFORME",IF(ABS(AS28)>5.05,"NO CONFORME","CONFORME")))) -> CONFORME | BD28: =SIGN(U28) -> -1 | BE28: =SIGN(AG28) -> -1 | BF28: =SIGN(AS28) -> -1 | BG28: =CONCATENATE(BD28,BE28,BF28) -> -1-1-1 | BH28: =IF(BG28="111","SI","SD") -> SD | BI28: =IF(BG28="-1-1-1","SI","SD") -> SI | BJ28: =OR(BH28="SI",BI28="SI") -> TRUE | BK28: =IF(BJ28=FALSE,"SIGDIFERENTES","SIGIGUALES") -> SIGIGUALES | BL28: =IF(BC28="NO CONFORME","NO CONFORME",IF(BB28="CONFORME","CONFORME","NO CONFORME")) -> CONFORME
A29: 21 | B29: =B28 -> 45920 | C29: =C28 -> 45920 | D29: =D28 -> 3 | E29: =E28 -> 8 | G29: PA25516885 | H29: =H28 -> 25.6 | I29: =I28 -> 0 | J29: =J28 -> 20.5 | K29: =K28 -> 8.487 | L29: =L28 -> 0.592 | M29: 102.85 | N29: 202.66 | O29: =O28 -> 100.31 | P29: =P28 -> 2,30,140 | Q29: =LEFT(P29,1) -> 2 | R29: =RIGHT(P29,6) -> 30,140 | S29: =+(Q29*60+R29)/(60*60) -> 0.041705556 | T29: =+O29/S29 -> 2405.1952 | U29: =+(((N29-M29-O29)/O29)*100) -> -0.49845479 | V29: =V28 -> 20.7 | W29: =W28 -> 1.095 | X29: =X28 -> 1.086 | Y29: 228.26 | Z29: 238.27 | AA29: =AA28 -> 10.008 | AB29: =AB28 -> 22,32,060 | AC29: =LEFT(AB29,2) -> 22 | AD29: =RIGHT(AB29,6) -> 32,060 | AE29: =+(AC29*60+AD29)/(60*60) -> 0.37557222 | AF29: =+AA29/AE29 -> 26.647338 | AG29: =+(((Z29-Y29-AA29)/AA29)*100) -> 0.019984013 | AH29: =AH28 -> 21.3 | AI29: =AI28 -> 1.096 | AJ29: =AJ28 -> 1.087 | AK29: =Z29 -> 238.27 | AL29: 243.29 | AM29: =AM28 -> 5.005 | AN29: =AN28 -> 18,09,850 | AO29: =LEFT(AN29,2) -> 18 | AP29: =RIGHT(AN29,6) -> 09,850 | AQ29: =+(AO29*60+AP29)/(60*60) -> 0.30273611 | AR29: =+AM29/AQ29 -> 16.53255 | AS29: =+(((AL29-AK29-AM29)/AM29)*100) -> 0.2997003 | AT29: =IF(I29>=1,"NO CONFORME",IF(BK29="SIGDIFERENTES",BC29,BL29)) -> CONFORME | AU29: =B29<=C29 -> TRUE | AV29: =N29<Y29 -> TRUE | AW29: =Z29<=AK29 -> TRUE | AX29: =IF(I29>=1,"Qcorrecto",IF(AND(AY29="aceptable",AZ29="aceptable",BA29="aceptable"),"Qcorrecto","Qincorrecto")) -> Qcorrecto | AY29: =IF(AR29<$AH$6,"error",IF(AR29>$AH$6*1.1,"error","aceptable")) -> aceptable | AZ29: =IF(AF29<$V$6,"error",IF(AF29>$V$6*1.1,"error","aceptable")) -> aceptable | BA29: =IF(T29<$J$6*0.9,"error",IF(T29>$J$6,"error","aceptable")) -> aceptable | BB29: =(IF(ABS(U29)<1.05,"CONFORME",IF(ABS(AG29)<1.05,"CONFORME",IF(ABS(AS29)<2.55,"CONFORME","NO CONFORME")))) -> CONFORME | BC29: =(IF(ABS(U29)>2.05,"NO CONFORME",IF(ABS(AG29)>2.05,"NO CONFORME",IF(ABS(AS29)>5.05,"NO CONFORME","CONFORME")))) -> CONFORME | BD29: =SIGN(U29) -> -1 | BE29: =SIGN(AG29) -> 1 | BF29: =SIGN(AS29) -> 1 | BG29: =CONCATENATE(BD29,BE29,BF29) -> -111 | BH29: =IF(BG29="111","SI","SD") -> SD | BI29: =IF(BG29="-1-1-1","SI","SD") -> SD | BJ29: =OR(BH29="SI",BI29="SI") -> FALSE | BK29: =IF(BJ29=FALSE,"SIGDIFERENTES","SIGIGUALES") -> SIGDIFERENTES | BL29: =IF(BC29="NO CONFORME","NO CONFORME",IF(BB29="CONFORME","CONFORME","NO CONFORME")) -> CONFORME
A30: 22 | B30: =B29 -> 45920 | C30: =C29 -> 45920 | D30: =D29 -> 3 | E30: =E29 -> 8 | G30: PA25516886 | H30: =H29 -> 25.6 | I30: =I29 -> 0 | J30: =J29 -> 20.5 | K30: =K29 -> 8.487 | L30: =L29 -> 0.592 | M30: 103.05 | N30: 203.68 | O30: =O29 -> 100.31 | P30: =P29 -> 2,30,140 | Q30: =LEFT(P30,1) -> 2 | R30: =RIGHT(P30,6) -> 30,140 | S30: =+(Q30*60+R30)/(60*60) -> 0.041705556 | T30: =+O30/S30 -> 2405.1952 | U30: =+(((N30-M30-O30)/O30)*100) -> 0.31901107 | V30: =V29 -> 20.7 | W30: =W29 -> 1.095 | X30: =X29 -> 1.086 | Y30: 229.3 | Z30: 239.33 | AA30: =AA29 -> 10.008 | AB30: =AB29 -> 22,32,060 | AC30: =LEFT(AB30,2) -> 22 | AD30: =RIGHT(AB30,6) -> 32,060 | AE30: =+(AC30*60+AD30)/(60*60) -> 0.37557222 | AF30: =+AA30/AE30 -> 26.647338 | AG30: =+(((Z30-Y30-AA30)/AA30)*100) -> 0.21982414 | AH30: =AH29 -> 21.3 | AI30: =AI29 -> 1.096 | AJ30: =AJ29 -> 1.087 | AK30: =Z30 -> 239.33 | AL30: 244.39 | AM30: =AM29 -> 5.005 | AN30: =AN29 -> 18,09,850 | AO30: =LEFT(AN30,2) -> 18 | AP30: =RIGHT(AN30,6) -> 09,850 | AQ30: =+(AO30*60+AP30)/(60*60) -> 0.30273611 | AR30: =+AM30/AQ30 -> 16.53255 | AS30: =+(((AL30-AK30-AM30)/AM30)*100) -> 1.0989011 | AT30: =IF(I30>=1,"NO CONFORME",IF(BK30="SIGDIFERENTES",BC30,BL30)) -> CONFORME | AU30: =B30<=C30 -> TRUE | AV30: =N30<Y30 -> TRUE | AW30: =Z30<=AK30 -> TRUE | AX30: =IF(I30>=1,"Qcorrecto",IF(AND(AY30="aceptable",AZ30="aceptable",BA30="aceptable"),"Qcorrecto","Qincorrecto")) -> Qcorrecto | AY30: =IF(AR30<$AH$6,"error",IF(AR30>$AH$6*1.1,"error","aceptable")) -> aceptable | AZ30: =IF(AF30<$V$6,"error",IF(AF30>$V$6*1.1,"error","aceptable")) -> aceptable | BA30: =IF(T30<$J$6*0.9,"error",IF(T30>$J$6,"error","aceptable")) -> aceptable | BB30: =(IF(ABS(U30)<1.05,"CONFORME",IF(ABS(AG30)<1.05,"CONFORME",IF(ABS(AS30)<2.55,"CONFORME","NO CONFORME")))) -> CONFORME | BC30: =(IF(ABS(U30)>2.05,"NO CONFORME",IF(ABS(AG30)>2.05,"NO CONFORME",IF(ABS(AS30)>5.05,"NO CONFORME","CONFORME")))) -> CONFORME | BD30: =SIGN(U30) -> 1 | BE30: =SIGN(AG30) -> 1 | BF30: =SIGN(AS30) -> 1 | BG30: =CONCATENATE(BD30,BE30,BF30) -> 111 | BH30: =IF(BG30="111","SI","SD") -> SI | BI30: =IF(BG30="-1-1-1","SI","SD") -> SD | BJ30: =OR(BH30="SI",BI30="SI") -> TRUE | BK30: =IF(BJ30=FALSE,"SIGDIFERENTES","SIGIGUALES") -> SIGIGUALES | BL30: =IF(BC30="NO CONFORME","NO CONFORME",IF(BB30="CONFORME","CONFORME","NO CONFORME")) -> CONFORME
A31: 23 | B31: =B30 -> 45920 | C31: =C30 -> 45920 | D31: =D30 -> 3 | E31: =E30 -> 8 | G31: PA25516887 | H31: =H30 -> 25.6 | I31: =I30 -> 0 | J31: =J30 -> 20.5 | K31: =K30 -> 8.487 | L31: =L30 -> 0.592 | M31: 101.11 | N31: 200.56 | O31: =O30 -> 100.31 | P31: =P30 -> 2,30,140 | Q31: =LEFT(P31,1) -> 2 | R31: =RIGHT(P31,6) -> 30,140 | S31: =+(Q31*60+R31)/(60*60) -> 0.041705556 | T31: =+O31/S31 -> 2405.1952 | U31: =+(((N31-M31-O31)/O31)*100) -> -0.85734224 | V31: =V30 -> 20.7 | W31: =W30 -> 1.095 | X31: =X30 -> 1.086 | Y31: 225.98 | Z31: 235.94 | AA31: =AA30 -> 10.008 | AB31: =AB30 -> 22,32,060 | AC31: =LEFT(AB31,2) -> 22 | AD31: =RIGHT(AB31,6) -> 32,060 | AE31: =+(AC31*60+AD31)/(60*60) -> 0.37557222 | AF31: =+AA31/AE31 -> 26.647338 | AG31: =+(((Z31-Y31-AA31)/AA31)*100) -> -0.47961631 | AH31: =AH30 -> 21.3 | AI31: =AI30 -> 1.096 | AJ31: =AJ30 -> 1.087 | AK31: =Z31 -> 235.94 | AL31: 240.97 | AM31: =AM30 -> 5.005 | AN31: =AN30 -> 18,09,850 | AO31: =LEFT(AN31,2) -> 18 | AP31: =RIGHT(AN31,6) -> 09,850 | AQ31: =+(AO31*60+AP31)/(60*60) -> 0.30273611 | AR31: =+AM31/AQ31 -> 16.53255 | AS31: =+(((AL31-AK31-AM31)/AM31)*100) -> 0.4995005 | AT31: =IF(I31>=1,"NO CONFORME",IF(BK31="SIGDIFERENTES",BC31,BL31)) -> CONFORME | AU31: =B31<=C31 -> TRUE | AV31: =N31<Y31 -> TRUE | AW31: =Z31<=AK31 -> TRUE | AX31: =IF(I31>=1,"Qcorrecto",IF(AND(AY31="aceptable",AZ31="aceptable",BA31="aceptable"),"Qcorrecto","Qincorrecto")) -> Qcorrecto | AY31: =IF(AR31<$AH$6,"error",IF(AR31>$AH$6*1.1,"error","aceptable")) -> aceptable | AZ31: =IF(AF31<$V$6,"error",IF(AF31>$V$6*1.1,"error","aceptable")) -> aceptable | BA31: =IF(T31<$J$6*0.9,"error",IF(T31>$J$6,"error","aceptable")) -> aceptable | BB31: =(IF(ABS(U31)<1.05,"CONFORME",IF(ABS(AG31)<1.05,"CONFORME",IF(ABS(AS31)<2.55,"CONFORME","NO CONFORME")))) -> CONFORME | BC31: =(IF(ABS(U31)>2.05,"NO CONFORME",IF(ABS(AG31)>2.05,"NO CONFORME",IF(ABS(AS31)>5.05,"NO CONFORME","CONFORME")))) -> CONFORME | BD31: =SIGN(U31) -> -1 | BE31: =SIGN(AG31) -> -1 | BF31: =SIGN(AS31) -> 1 | BG31: =CONCATENATE(BD31,BE31,BF31) -> -1-11 | BH31: =IF(BG31="111","SI","SD") -> SD | BI31: =IF(BG31="-1-1-1","SI","SD") -> SD | BJ31: =OR(BH31="SI",BI31="SI") -> FALSE | BK31: =IF(BJ31=FALSE,"SIGDIFERENTES","SIGIGUALES") -> SIGDIFERENTES | BL31: =IF(BC31="NO CONFORME","NO CONFORME",IF(BB31="CONFORME","CONFORME","NO CONFORME")) -> CONFORME
A32: 24 | B32: =B31 -> 45920 | C32: =C31 -> 45920 | D32: =D31 -> 3 | E32: =E31 -> 8 | G32: PA25516888 | H32: =H31 -> 25.6 | I32: =I31 -> 0 | J32: =J31 -> 20.5 | K32: =K31 -> 8.487 | L32: =L31 -> 0.592 | M32: 102.55 | N32: 201.48 | O32: =O31 -> 100.31 | P32: =P31 -> 2,30,140 | Q32: =LEFT(P32,1) -> 2 | R32: =RIGHT(P32,6) -> 30,140 | S32: =+(Q32*60+R32)/(60*60) -> 0.041705556 | T32: =+O32/S32 -> 2405.1952 | U32: =+(((N32-M32-O32)/O32)*100) -> -1.3757352 | V32: =V31 -> 20.7 | W32: =W31 -> 1.095 | X32: =X31 -> 1.086 | Y32: 226.7 | Z32: 236.61 | AA32: =AA31 -> 10.008 | AB32: =AB31 -> 22,32,060 | AC32: =LEFT(AB32,2) -> 22 | AD32: =RIGHT(AB32,6) -> 32,060 | AE32: =+(AC32*60+AD32)/(60*60) -> 0.37557222 | AF32: =+AA32/AE32 -> 26.647338 | AG32: =+(((Z32-Y32-AA32)/AA32)*100) -> -0.97921663 | AH32: =AH31 -> 21.3 | AI32: =AI31 -> 1.096 | AJ32: =AJ31 -> 1.087 | AK32: =Z32 -> 236.61 | AL32: 241.56 | AM32: =AM31 -> 5.005 | AN32: =AN31 -> 18,09,850 | AO32: =LEFT(AN32,2) -> 18 | AP32: =RIGHT(AN32,6) -> 09,850 | AQ32: =+(AO32*60+AP32)/(60*60) -> 0.30273611 | AR32: =+AM32/AQ32 -> 16.53255 | AS32: =+(((AL32-AK32-AM32)/AM32)*100) -> -1.0989011 | AT32: =IF(I32>=1,"NO CONFORME",IF(BK32="SIGDIFERENTES",BC32,BL32)) -> CONFORME | AU32: =B32<=C32 -> TRUE | AV32: =N32<Y32 -> TRUE | AW32: =Z32<=AK32 -> TRUE | AX32: =IF(I32>=1,"Qcorrecto",IF(AND(AY32="aceptable",AZ32="aceptable",BA32="aceptable"),"Qcorrecto","Qincorrecto")) -> Qcorrecto | AY32: =IF(AR32<$AH$6,"error",IF(AR32>$AH$6*1.1,"error","aceptable")) -> aceptable | AZ32: =IF(AF32<$V$6,"error",IF(AF32>$V$6*1.1,"error","aceptable")) -> aceptable | BA32: =IF(T32<$J$6*0.9,"error",IF(T32>$J$6,"error","aceptable")) -> aceptable | BB32: =(IF(ABS(U32)<1.05,"CONFORME",IF(ABS(AG32)<1.05,"CONFORME",IF(ABS(AS32)<2.55,"CONFORME","NO CONFORME")))) -> CONFORME | BC32: =(IF(ABS(U32)>2.05,"NO CONFORME",IF(ABS(AG32)>2.05,"NO CONFORME",IF(ABS(AS32)>5.05,"NO CONFORME","CONFORME")))) -> CONFORME | BD32: =SIGN(U32) -> -1 | BE32: =SIGN(AG32) -> -1 | BF32: =SIGN(AS32) -> -1 | BG32: =CONCATENATE(BD32,BE32,BF32) -> -1-1-1 | BH32: =IF(BG32="111","SI","SD") -> SD | BI32: =IF(BG32="-1-1-1","SI","SD") -> SI | BJ32: =OR(BH32="SI",BI32="SI") -> TRUE | BK32: =IF(BJ32=FALSE,"SIGDIFERENTES","SIGIGUALES") -> SIGIGUALES | BL32: =IF(BC32="NO CONFORME","NO CONFORME",IF(BB32="CONFORME","CONFORME","NO CONFORME")) -> CONFORME
A33: 25 | B33: =B32 -> 45920 | C33: =C32 -> 45920 | D33: =D32 -> 3 | E33: =E32 -> 8 | G33: PA25516889 | H33: =H32 -> 25.6 | I33: =I32 -> 0 | J33: =J32 -> 20.5 | K33: =K32 -> 8.487 | L33: =L32 -> 0.592 | M33: 142.43 | N33: 242.08 | O33: =O32 -> 100.31 | P33: =P32 -> 2,30,140 | Q33: =LEFT(P33,1) -> 2 | R33: =RIGHT(P33,6) -> 30,140 | S33: =+(Q33*60+R33)/(60*60) -> 0.041705556 | T33: =+O33/S33 -> 2405.1952 | U33: =+(((N33-M33-O33)/O33)*100) -> -0.65796032 | V33: =V32 -> 20.7 | W33: =W32 -> 1.095 | X33: =X32 -> 1.086 | Y33: 267.48 | Z33: 277.41 | AA33: =AA32 -> 10.008 | AB33: =AB32 -> 22,32,060 | AC33: =LEFT(AB33,2) -> 22 | AD33: =RIGHT(AB33,6) -> 32,060 | AE33: =+(AC33*60+AD33)/(60*60) -> 0.37557222 | AF33: =+AA33/AE33 -> 26.647338 | AG33: =+(((Z33-Y33-AA33)/AA33)*100) -> -0.7793765 | AH33: =AH32 -> 21.3 | AI33: =AI32 -> 1.096 | AJ33: =AJ32 -> 1.087 | AK33: =Z33 -> 277.41 | AL33: 282.42 | AM33: =AM32 -> 5.005 | AN33: =AN32 -> 18,09,850 | AO33: =LEFT(AN33,2) -> 18 | AP33: =RIGHT(AN33,6) -> 09,850 | AQ33: =+(AO33*60+AP33)/(60*60) -> 0.30273611 | AR33: =+AM33/AQ33 -> 16.53255 | AS33: =+(((AL33-AK33-AM33)/AM33)*100) -> 0.0999001 | AT33: =IF(I33>=1,"NO CONFORME",IF(BK33="SIGDIFERENTES",BC33,BL33)) -> CONFORME | AU33: =B33<=C33 -> TRUE | AV33: =N33<Y33 -> TRUE | AW33: =Z33<=AK33 -> TRUE | AX33: =IF(I33>=1,"Qcorrecto",IF(AND(AY33="aceptable",AZ33="aceptable",BA33="aceptable"),"Qcorrecto","Qincorrecto")) -> Qcorrecto | AY33: =IF(AR33<$AH$6,"error",IF(AR33>$AH$6*1.1,"error","aceptable")) -> aceptable | AZ33: =IF(AF33<$V$6,"error",IF(AF33>$V$6*1.1,"error","aceptable")) -> aceptable | BA33: =IF(T33<$J$6*0.9,"error",IF(T33>$J$6,"error","aceptable")) -> aceptable | BB33: =(IF(ABS(U33)<1.05,"CONFORME",IF(ABS(AG33)<1.05,"CONFORME",IF(ABS(AS33)<2.55,"CONFORME","NO CONFORME")))) -> CONFORME | BC33: =(IF(ABS(U33)>2.05,"NO CONFORME",IF(ABS(AG33)>2.05,"NO CONFORME",IF(ABS(AS33)>5.05,"NO CONFORME","CONFORME")))) -> CONFORME | BD33: =SIGN(U33) -> -1 | BE33: =SIGN(AG33) -> -1 | BF33: =SIGN(AS33) -> 1 | BG33: =CONCATENATE(BD33,BE33,BF33) -> -1-11 | BH33: =IF(BG33="111","SI","SD") -> SD | BI33: =IF(BG33="-1-1-1","SI","SD") -> SD | BJ33: =OR(BH33="SI",BI33="SI") -> FALSE | BK33: =IF(BJ33=FALSE,"SIGDIFERENTES","SIGIGUALES") -> SIGDIFERENTES | BL33: =IF(BC33="NO CONFORME","NO CONFORME",IF(BB33="CONFORME","CONFORME","NO CONFORME")) -> CONFORME
A34: 26 | B34: =B33 -> 45920 | C34: =C33 -> 45920 | D34: =D33 -> 3 | E34: =E33 -> 8 | G34: PA25516890 | H34: =H33 -> 25.6 | I34: =I33 -> 0 | J34: =J33 -> 20.5 | K34: =K33 -> 8.487 | L34: =L33 -> 0.592 | M34: 101.45 | N34: 200.55 | O34: =O33 -> 100.31 | P34: =P33 -> 2,30,140 | Q34: =LEFT(P34,1) -> 2 | R34: =RIGHT(P34,6) -> 30,140 | S34: =+(Q34*60+R34)/(60*60) -> 0.041705556 | T34: =+O34/S34 -> 2405.1952 | U34: =+(((N34-M34-O34)/O34)*100) -> -1.2062606 | V34: =V33 -> 20.7 | W34: =W33 -> 1.095 | X34: =X33 -> 1.086 | Y34: 225.88 | Z34: 235.79 | AA34: =AA33 -> 10.008 | AB34: =AB33 -> 22,32,060 | AC34: =LEFT(AB34,2) -> 22 | AD34: =RIGHT(AB34,6) -> 32,060 | AE34: =+(AC34*60+AD34)/(60*60) -> 0.37557222 | AF34: =+AA34/AE34 -> 26.647338 | AG34: =+(((Z34-Y34-AA34)/AA34)*100) -> -0.97921663 | AH34: =AH33 -> 21.3 | AI34: =AI33 -> 1.096 | AJ34: =AJ33 -> 1.087 | AK34: =Z34 -> 235.79 | AL34: 240.79 | AM34: =AM33 -> 5.005 | AN34: =AN33 -> 18,09,850 | AO34: =LEFT(AN34,2) -> 18 | AP34: =RIGHT(AN34,6) -> 09,850 | AQ34: =+(AO34*60+AP34)/(60*60) -> 0.30273611 | AR34: =+AM34/AQ34 -> 16.53255 | AS34: =+(((AL34-AK34-AM34)/AM34)*100) -> -0.0999001 | AT34: =IF(I34>=1,"NO CONFORME",IF(BK34="SIGDIFERENTES",BC34,BL34)) -> CONFORME | AU34: =B34<=C34 -> TRUE | AV34: =N34<Y34 -> TRUE | AW34: =Z34<=AK34 -> TRUE | AX34: =IF(I34>=1,"Qcorrecto",IF(AND(AY34="aceptable",AZ34="aceptable",BA34="aceptable"),"Qcorrecto","Qincorrecto")) -> Qcorrecto | AY34: =IF(AR34<$AH$6,"error",IF(AR34>$AH$6*1.1,"error","aceptable")) -> aceptable | AZ34: =IF(AF34<$V$6,"error",IF(AF34>$V$6*1.1,"error","aceptable")) -> aceptable | BA34: =IF(T34<$J$6*0.9,"error",IF(T34>$J$6,"error","aceptable")) -> aceptable | BB34: =(IF(ABS(U34)<1.05,"CONFORME",IF(ABS(AG34)<1.05,"CONFORME",IF(ABS(AS34)<2.55,"CONFORME","NO CONFORME")))) -> CONFORME | BC34: =(IF(ABS(U34)>2.05,"NO CONFORME",IF(ABS(AG34)>2.05,"NO CONFORME",IF(ABS(AS34)>5.05,"NO CONFORME","CONFORME")))) -> CONFORME | BD34: =SIGN(U34) -> -1 | BE34: =SIGN(AG34) -> -1 | BF34: =SIGN(AS34) -> -1 | BG34: =CONCATENATE(BD34,BE34,BF34) -> -1-1-1 | BH34: =IF(BG34="111","SI","SD") -> SD | BI34: =IF(BG34="-1-1-1","SI","SD") -> SI | BJ34: =OR(BH34="SI",BI34="SI") -> TRUE | BK34: =IF(BJ34=FALSE,"SIGDIFERENTES","SIGIGUALES") -> SIGIGUALES | BL34: =IF(BC34="NO CONFORME","NO CONFORME",IF(BB34="CONFORME","CONFORME","NO CONFORME")) -> CONFORME
A35: 27 | B35: =B34 -> 45920 | C35: =C34 -> 45920 | D35: =D34 -> 3 | E35: =E34 -> 8 | G35: PA25516891 | H35: =H34 -> 25.6 | I35: =I34 -> 0 | J35: =J34 -> 20.5 | K35: =K34 -> 8.487 | L35: =L34 -> 0.592 | M35: 100.33 | N35: 200.09 | O35: =O34 -> 100.31 | P35: =P34 -> 2,30,140 | Q35: =LEFT(P35,1) -> 2 | R35: =RIGHT(P35,6) -> 30,140 | S35: =+(Q35*60+R35)/(60*60) -> 0.041705556 | T35: =+O35/S35 -> 2405.1952 | U35: =+(((N35-M35-O35)/O35)*100) -> -0.54830027 | V35: =V34 -> 20.7 | W35: =W34 -> 1.095 | X35: =X34 -> 1.086 | Y35: 225.52 | Z35: 235.45 | AA35: =AA34 -> 10.008 | AB35: =AB34 -> 22,32,060 | AC35: =LEFT(AB35,2) -> 22 | AD35: =RIGHT(AB35,6) -> 32,060 | AE35: =+(AC35*60+AD35)/(60*60) -> 0.37557222 | AF35: =+AA35/AE35 -> 26.647338 | AG35: =+(((Z35-Y35-AA35)/AA35)*100) -> -0.7793765 | AH35: =AH34 -> 21.3 | AI35: =AI34 -> 1.096 | AJ35: =AJ34 -> 1.087 | AK35: =Z35 -> 235.45 | AL35: 240.44 | AM35: =AM34 -> 5.005 | AN35: =AN34 -> 18,09,850 | AO35: =LEFT(AN35,2) -> 18 | AP35: =RIGHT(AN35,6) -> 09,850 | AQ35: =+(AO35*60+AP35)/(60*60) -> 0.30273611 | AR35: =+AM35/AQ35 -> 16.53255 | AS35: =+(((AL35-AK35-AM35)/AM35)*100) -> -0.2997003 | AT35: =IF(I35>=1,"NO CONFORME",IF(BK35="SIGDIFERENTES",BC35,BL35)) -> CONFORME | AU35: =B35<=C35 -> TRUE | AV35: =N35<Y35 -> TRUE | AW35: =Z35<=AK35 -> TRUE | AX35: =IF(I35>=1,"Qcorrecto",IF(AND(AY35="aceptable",AZ35="aceptable",BA35="aceptable"),"Qcorrecto","Qincorrecto")) -> Qcorrecto | AY35: =IF(AR35<$AH$6,"error",IF(AR35>$AH$6*1.1,"error","aceptable")) -> aceptable | AZ35: =IF(AF35<$V$6,"error",IF(AF35>$V$6*1.1,"error","aceptable")) -> aceptable | BA35: =IF(T35<$J$6*0.9,"error",IF(T35>$J$6,"error","aceptable")) -> aceptable | BB35: =(IF(ABS(U35)<1.05,"CONFORME",IF(ABS(AG35)<1.05,"CONFORME",IF(ABS(AS35)<2.55,"CONFORME","NO CONFORME")))) -> CONFORME | BC35: =(IF(ABS(U35)>2.05,"NO CONFORME",IF(ABS(AG35)>2.05,"NO CONFORME",IF(ABS(AS35)>5.05,"NO CONFORME","CONFORME")))) -> CONFORME | BD35: =SIGN(U35) -> -1 | BE35: =SIGN(AG35) -> -1 | BF35: =SIGN(AS35) -> -1 | BG35: =CONCATENATE(BD35,BE35,BF35) -> -1-1-1 | BH35: =IF(BG35="111","SI","SD") -> SD | BI35: =IF(BG35="-1-1-1","SI","SD") -> SI | BJ35: =OR(BH35="SI",BI35="SI") -> TRUE | BK35: =IF(BJ35=FALSE,"SIGDIFERENTES","SIGIGUALES") -> SIGIGUALES | BL35: =IF(BC35="NO CONFORME","NO CONFORME",IF(BB35="CONFORME","CONFORME","NO CONFORME")) -> CONFORME
